Workbook

Sheet Read Me
A1: PnL Analysis of Trading Algorithms — Read Me, Methodology & Verdict
A3: Source data
A4: Built from the JSON files in the dhanhq repository. The daily P&L breakdown (GetHistoricalPnlBreakdown) is the primary source; period aggregates and the platform QuantStats files were used to validate every computed figure.
A5: Each strategy has its own D_ tab holding the daily P&L (input) plus live formula columns for cumulative return, running peak, drawdown, recovery and the ex-Wednesday variants. Every summary number (except XIRR) is a live formula reading those tabs.
A7: Capital basis
A8: Individual algos: each strategy is analysed on its own native Max Allocation — Rs 3,20,000 for the five credit spreads and Rs 5,00,000 for both SkewHunter variants (matching the platform book size).
A9: Combinations: each credit spread is sized at Rs 3.2L; option-buying (SkewHunter TSL) is sized at Rs 1L. Because TSL is recorded on a 5L book, its daily P&L is scaled by 1L / 5L = 0.2.
A10: Combination 1 = 5 credit spreads (Curvature, Damper, Zen, Delta-Ripple, Delta-Rotation) — capital Rs 16.0L.
A11: Combination 2 = identical to Combination 1 in the prompt (processed as written) — capital Rs 16.0L.
A12: Combination 3 = 5 credit spreads + SkewHunter TSL — capital Rs 17.0L.
A14: Methodology
A15: Return % = sum of daily P&L over the window / Max Allocation. CAGR = (1 + total return)^(365 / calendar days) - 1.
... A20: Colour legend
A21: Positive | B21: gains | C21: Negative | D21: losses
A23: Key findings
A24: 1. Wednesday is the worst weekday for almost every strategy (negative total P&L). Removing Wednesday lifts returns AND shrinks drawdowns across the board — see the "Excluding Wednesday" block on each stats sheet.
A25: 2. Diversifying the five credit spreads is powerful: individual max drawdowns of -20% to -44% collapse to about -8% when combined, because the strategies draw down at different times.
A26: 3. Combination results (basis Max Allocation, including Wednesday):
A27: Combination | B27: Capital | C27: Max Return | D27: Max Drawdown | E27: CAGR | F27: Calmar (Ret/|DD|)
A28: Combination 1 | B28: Rs 16.0L | C28: 142 | D28: -8.31 | E28: 145 | F28: 17.1
A29: Combination 2 | B29: Rs 16.0L | C29: 142 | D29: -8.31 | E29: 145 | F29: 17.1
A30: Combination 3 | B30: Rs 17.0L | C30: 146.6 | D30: -9.35 | E30: 147.2 | F30: 15.7
A32: Verdict
A33: Most profitable on absolute return: Combination 3 (5 credit spreads + SkewHunter TSL) at 146.6% on Rs 17L, edging out Combinations 1/2 at 142.0%.
A34: Best on drawdown / risk-adjusted: Combinations 1 & 2 (5 credit spreads only) — shallower max drawdown of -8.3% vs -9.4%, and the highest Calmar ratio (~17.1 vs ~15.7). Adding the option-buying leg lifts return slightly but deepens the drawdown.
A35: Practical read: the pure 5-credit-spread book (Comb 1/2) gives the smoothest ride for nearly the same return; add SkewHunter TSL (Comb 3) only if the extra ~4.6 points of return are worth a ~1 point deeper drawdown. Both improve further if Wednesday is skipped.
A37: Note: short-window returns (1M/3M) and the annualised CAGR/XIRR are sensitive to start date and limited history; treat them as indicative. Combination 1 and 2 are identical by the prompt definition.

Sheet Individual - Stats A
A1: Stats A — Statistics A (basis Max Allocation)
A2: Including Wednesday
A3: Metric | B3: Curvature | C3: Damper | D3: Zen | E3: Delta-Ripple | F3: Delta-Rotation | G3: SkewHunter | H3: SkewHunter TSL
A4: Type | B4: Credit | C4: Credit | D4: Credit | E4: Credit | F4: Credit | G4: Option | H4: Option
A5: Allocation (Rs) | B5: =D_CURV!$T$1 -> 320000 | C5: =D_DAMP!$T$1 -> 320000 | D5: =D_ZEN!$T$1 -> 320000 | E5: =D_DRIP!$T$1 -> 320000 | F5: =D_DROT!$T$1 -> 320000 | G5: =D_SKEW!$T$1 -> 500000 | H5: =D_SKEWTSL!$T$1 -> 500000
A6: Return 1M | B6: =SUMIFS(D_CURV!$C$2:$C$116,D_CURV!$A$2:$A$116,">="&D_CURV!$T$3)/D_CURV!$T$1*100 -> 22.624063 | C6: =SUMIFS(D_DAMP!$C$2:$C$155,D_DAMP!$A$2:$A$155,">="&D_DAMP!$T$3)/D_DAMP!$T$1*100 -> 12.357109 | D6: =SUMIFS(D_ZEN!$C$2:$C$137,D_ZEN!$A$2:$A$137,">="&D_ZEN!$T$3)/D_ZEN!$T$1*100 -> 8.0122656 | E6: =SUMIFS(D_DRIP!$C$2:$C$128,D_DRIP!$A$2:$A$128,">="&D_DRIP!$T$3)/D_DRIP!$T$1*100 -> 26.207187 | F6: =SUMIFS(D_DROT!$C$2:$C$122,D_DROT!$A$2:$A$122,">="&D_DROT!$T$3)/D_DROT!$T$1*100 -> 14.883984 | G6: =SUMIFS(D_SKEW!$C$2:$C$236,D_SKEW!$A$2:$A$236,">="&D_SKEW!$T$3)/D_SKEW!$T$1*100 -> 37.0461 | H6: =SUMIFS(D_SKEWTSL!$C$2:$C$237,D_SKEWTSL!$A$2:$A$237,">="&D_SKEWTSL!$T$3)/D_SKEWTSL!$T$1*100 -> 31.29815
A7: Return 3M | B7: =SUMIFS(D_CURV!$C$2:$C$116,D_CURV!$A$2:$A$116,">="&D_CURV!$T$4)/D_CURV!$T$1*100 -> 55.010312 | C7: =SUMIFS(D_DAMP!$C$2:$C$155,D_DAMP!$A$2:$A$155,">="&D_DAMP!$T$4)/D_DAMP!$T$1*100 -> 22.454453 | D7: =SUMIFS(D_ZEN!$C$2:$C$137,D_ZEN!$A$2:$A$137,">="&D_ZEN!$T$4)/D_ZEN!$T$1*100 -> 55.730391 | E7: =SUMIFS(D_DRIP!$C$2:$C$128,D_DRIP!$A$2:$A$128,">="&D_DRIP!$T$4)/D_DRIP!$T$1*100 -> 81.167734 | F7: =SUMIFS(D_DROT!$C$2:$C$122,D_DROT!$A$2:$A$122,">="&D_DROT!$T$4)/D_DROT!$T$1*100 -> 59.483125 | G7: =SUMIFS(D_SKEW!$C$2:$C$236,D_SKEW!$A$2:$A$236,">="&D_SKEW!$T$4)/D_SKEW!$T$1*100 -> 31.9514 | H7: =SUMIFS(D_SKEWTSL!$C$2:$C$237,D_SKEWTSL!$A$2:$A$237,">="&D_SKEWTSL!$T$4)/D_SKEWTSL!$T$1*100 -> 55.1915
A8: Return 6M | B8: =SUMIFS(D_CURV!$C$2:$C$116,D_CURV!$A$2:$A$116,">="&D_CURV!$T$5)/D_CURV!$T$1*100 -> 94.767813 | C8: =SUMIFS(D_DAMP!$C$2:$C$155,D_DAMP!$A$2:$A$155,">="&D_DAMP!$T$5)/D_DAMP!$T$1*100 -> 81.463672 | D8: =SUMIFS(D_ZEN!$C$2:$C$137,D_ZEN!$A$2:$A$137,">="&D_ZEN!$T$5)/D_ZEN!$T$1*100 -> 70.568906 | E8: =SUMIFS(D_DRIP!$C$2:$C$128,D_DRIP!$A$2:$A$128,">="&D_DRIP!$T$5)/D_DRIP!$T$1*100 -> 97.75285 | F8: =SUMIFS(D_DROT!$C$2:$C$122,D_DROT!$A$2:$A$122,">="&D_DROT!$T$5)/D_DROT!$T$1*100 -> 103.22131 | G8: =SUMIFS(D_SKEW!$C$2:$C$236,D_SKEW!$A$2:$A$236,">="&D_SKEW!$T$5)/D_SKEW!$T$1*100 -> 121.9663 | H8: =SUMIFS(D_SKEWTSL!$C$2:$C$237,D_SKEWTSL!$A$2:$A$237,">="&D_SKEWTSL!$T$5)/D_SKEWTSL!$T$1*100 -> 109.18985
A9: Return 1Y | B9: =SUMIFS(D_CURV!$C$2:$C$116,D_CURV!$A$2:$A$116,">="&D_CURV!$T$6)/D_CURV!$T$1*100 -> 183.28305 | C9: =SUMIFS(D_DAMP!$C$2:$C$155,D_DAMP!$A$2:$A$155,">="&D_DAMP!$T$6)/D_DAMP!$T$1*100 -> 114.61719 | D9: =SUMIFS(D_ZEN!$C$2:$C$137,D_ZEN!$A$2:$A$137,">="&D_ZEN!$T$6)/D_ZEN!$T$1*100 -> 163.61461 | E9: =SUMIFS(D_DRIP!$C$2:$C$128,D_DRIP!$A$2:$A$128,">="&D_DRIP!$T$6)/D_DRIP!$T$1*100 -> 143.49788 | F9: =SUMIFS(D_DROT!$C$2:$C$122,D_DROT!$A$2:$A$122,">="&D_DROT!$T$6)/D_DROT!$T$1*100 -> 105.04004 | G9: =SUMIFS(D_SKEW!$C$2:$C$236,D_SKEW!$A$2:$A$236,">="&D_SKEW!$T$6)/D_SKEW!$T$1*100 -> 341.9968 | H9: =SUMIFS(D_SKEWTSL!$C$2:$C$237,D_SKEWTSL!$A$2:$A$237,">="&D_SKEWTSL!$T$6)/D_SKEWTSL!$T$1*100 -> 219.7886
A10: Return Max | B10: =SUM(D_CURV!$C$2:$C$116)/D_CURV!$T$1*100 -> 183.28305 | C10: =SUM(D_DAMP!$C$2:$C$155)/D_DAMP!$T$1*100 -> 114.61719 | D10: =SUM(D_ZEN!$C$2:$C$137)/D_ZEN!$T$1*100 -> 163.61461 | E10: =SUM(D_DRIP!$C$2:$C$128)/D_DRIP!$T$1*100 -> 143.49788 | F10: =SUM(D_DROT!$C$2:$C$122)/D_DROT!$T$1*100 -> 105.04004 | G10: =SUM(D_SKEW!$C$2:$C$236)/D_SKEW!$T$1*100 -> 341.9968 | H10: =SUM(D_SKEWTSL!$C$2:$C$237)/D_SKEWTSL!$T$1*100 -> 219.7886
A11: Gross Gain (Rs) | B11: =SUM(D_CURV!$C$2:$C$116) -> 586505.75 | C11: =SUM(D_DAMP!$C$2:$C$155) -> 366775 | D11: =SUM(D_ZEN!$C$2:$C$137) -> 523566.75 | E11: =SUM(D_DRIP!$C$2:$C$128) -> 459193.21 | F11: =SUM(D_DROT!$C$2:$C$122) -> 336128.13 | G11: =SUM(D_SKEW!$C$2:$C$236) -> 1709984 | H11: =SUM(D_SKEWTSL!$C$2:$C$237) -> 1098943
A12: CAGR | B12: =((1+SUM(D_CURV!$C$2:$C$116)/D_CURV!$T$1)^(365/(D_CURV!$T$2-D_CURV!$T$9))-1)*100 -> 239.42295 | C12: =((1+SUM(D_DAMP!$C$2:$C$155)/D_DAMP!$T$1)^(365/(D_DAMP!$T$2-D_DAMP!$T$9))-1)*100 -> 195.82919 | D12: =((1+SUM(D_ZEN!$C$2:$C$137)/D_ZEN!$T$1)^(365/(D_ZEN!$T$2-D_ZEN!$T$9))-1)*100 -> 195.04583 | E12: =((1+SUM(D_DRIP!$C$2:$C$128)/D_DRIP!$T$1)^(365/(D_DRIP!$T$2-D_DRIP!$T$9))-1)*100 -> 155.0022 | F12: =((1+SUM(D_DROT!$C$2:$C$122)/D_DROT!$T$1)^(365/(D_DROT!$T$2-D_DROT!$T$9))-1)*100 -> 108.36591 | G12: =((1+SUM(D_SKEW!$C$2:$C$236)/D_SKEW!$T$1)^(365/(D_SKEW!$T$2-D_SKEW!$T$9))-1)*100 -> 343.80507 | H12: =((1+SUM(D_SKEWTSL!$C$2:$C$237)/D_SKEWTSL!$T$1)^(365/(D_SKEWTSL!$T$2-D_SKEWTSL!$T$9))-1)*100 -> 220.81153
A13: XIRR | B13: 650 | C13: 454 | D13: 630.3 | E13: 312.8 | F13: 122.3 | G13: 3508 | H13: 452.3
A14: Avg Drawdown | B14: =AVERAGE(D_CURV!$G$2:$G$116) -> -4.0110143 | C14: =AVERAGE(D_DAMP!$G$2:$G$155) -> -4.1502222 | D14: =AVERAGE(D_ZEN!$G$2:$G$137) -> -6.3859863 | E14: =AVERAGE(D_DRIP!$G$2:$G$128) -> -7.8163688 | F14: =AVERAGE(D_DROT!$G$2:$G$122) -> -15.064769 | G14: =AVERAGE(D_SKEW!$G$2:$G$236) -> -14.16245 | H14: =AVERAGE(D_SKEWTSL!$G$2:$G$237) -> -18.912963
A15: Max Drawdown | B15: =MIN(D_CURV!$G$2:$G$116) -> -22.170078 | C15: =MIN(D_DAMP!$G$2:$G$155) -> -20.276953 | D15: =MIN(D_ZEN!$G$2:$G$137) -> -25.385859 | E15: =MIN(D_DRIP!$G$2:$G$128) -> -32.356781 | F15: =MIN(D_DROT!$G$2:$G$122) -> -44.343144 | G15: =MIN(D_SKEW!$G$2:$G$236) -> -41.04225 | H15: =MIN(D_SKEWTSL!$G$2:$G$237) -> -68.33025
A16: Success Ratio | B16: =COUNTIF(D_CURV!$C$2:$C$116,">0")/(COUNTIF(D_CURV!$C$2:$C$116,">0")+COUNTIF(D_CURV!$C$2:$C$116,"<0"))*100 -> 60 | C16: =COUNTIF(D_DAMP!$C$2:$C$155,">0")/(COUNTIF(D_DAMP!$C$2:$C$155,">0")+COUNTIF(D_DAMP!$C$2:$C$155,"<0"))*100 -> 64.285714 | D16: =COUNTIF(D_ZEN!$C$2:$C$137,">0")/(COUNTIF(D_ZEN!$C$2:$C$137,">0")+COUNTIF(D_ZEN!$C$2:$C$137,"<0"))*100 -> 61.764706 | E16: =COUNTIF(D_DRIP!$C$2:$C$128,">0")/(COUNTIF(D_DRIP!$C$2:$C$128,">0")+COUNTIF(D_DRIP!$C$2:$C$128,"<0"))*100 -> 55.11811 | F16: =COUNTIF(D_DROT!$C$2:$C$122,">0")/(COUNTIF(D_DROT!$C$2:$C$122,">0")+COUNTIF(D_DROT!$C$2:$C$122,"<0"))*100 -> 52.066116 | G16: =COUNTIF(D_SKEW!$C$2:$C$236,">0")/(COUNTIF(D_SKEW!$C$2:$C$236,">0")+COUNTIF(D_SKEW!$C$2:$C$236,"<0"))*100 -> 44.680851 | H16: =COUNTIF(D_SKEWTSL!$C$2:$C$237,">0")/(COUNTIF(D_SKEWTSL!$C$2:$C$237,">0")+COUNTIF(D_SKEWTSL!$C$2:$C$237,"<0"))*100 -> 43.644068
A17: Risk : Reward | B17: =AVERAGEIF(D_CURV!$C$2:$C$116,">0")/-AVERAGEIF(D_CURV!$C$2:$C$116,"<0") -> 1.240113 | C17: =AVERAGEIF(D_DAMP!$C$2:$C$155,">0")/-AVERAGEIF(D_DAMP!$C$2:$C$155,"<0") -> 0.91727902 | D17: =AVERAGEIF(D_ZEN!$C$2:$C$137,">0")/-AVERAGEIF(D_ZEN!$C$2:$C$137,"<0") -> 0.99280896 | E17: =AVERAGEIF(D_DRIP!$C$2:$C$128,">0")/-AVERAGEIF(D_DRIP!$C$2:$C$128,"<0") -> 1.2198003 | F17: =AVERAGEIF(D_DROT!$C$2:$C$122,">0")/-AVERAGEIF(D_DROT!$C$2:$C$122,"<0") -> 1.2785427 | G17: =AVERAGEIF(D_SKEW!$C$2:$C$236,">0")/-AVERAGEIF(D_SKEW!$C$2:$C$236,"<0") -> 1.8941501 | H17: =AVERAGEIF(D_SKEWTSL!$C$2:$C$237,">0")/-AVERAGEIF(D_SKEWTSL!$C$2:$C$237,"<0") -> 1.8147473
A18: Avg Profit /day (Rs) | B18: =AVERAGEIF(D_CURV!$C$2:$C$116,">0") -> 18381.953 | C18: =AVERAGEIF(D_DAMP!$C$2:$C$155,">0") -> 9394.8384 | D18: =AVERAGEIF(D_ZEN!$C$2:$C$137,">0") -> 16556.33 | E18: =AVERAGEIF(D_DRIP!$C$2:$C$128,">0") -> 19732.39 | F18: =AVERAGEIF(D_DROT!$C$2:$C$122,">0") -> 19059.365 | G18: =AVERAGEIF(D_SKEW!$C$2:$C$236,">0") -> 47019.39 | H18: =AVERAGEIF(D_SKEWTSL!$C$2:$C$237,">0") -> 36987.051
A19: Avg Loss /day (Rs) | B19: =AVERAGEIF(D_CURV!$C$2:$C$116,"<0") -> -14822.804 | C19: =AVERAGEIF(D_DAMP!$C$2:$C$155,"<0") -> -10242.073 | D19: =AVERAGEIF(D_ZEN!$C$2:$C$137,"<0") -> -16676.25 | E19: =AVERAGEIF(D_DRIP!$C$2:$C$128,"<0") -> -16176.738 | F19: =AVERAGEIF(D_DROT!$C$2:$C$122,"<0") -> -14907.101 | G19: =AVERAGEIF(D_SKEW!$C$2:$C$236,"<0") -> -24823.477 | H19: =AVERAGEIF(D_SKEWTSL!$C$2:$C$237,"<0") -> -20381.378
A20: Avg Recovery (days) | B20: =AVERAGEIF(D_CURV!$J$2:$J$116,">0") -> 11.714286 | C20: =AVERAGEIF(D_DAMP!$J$2:$J$155,">0") -> 11.058824 | D20: =AVERAGEIF(D_ZEN!$J$2:$J$137,">0") -> 14 | E20: =AVERAGEIF(D_DRIP!$J$2:$J$128,">0") -> 14.421053 | F20: =AVERAGEIF(D_DROT!$J$2:$J$122,">0") -> 27.909091 | G20: =AVERAGEIF(D_SKEW!$J$2:$J$236,">0") -> 13.8 | H20: =AVERAGEIF(D_SKEWTSL!$J$2:$J$237,">0") -> 18.666667
A21: Max Recovery (days) | B21: =MAX(MAX(D_CURV!$J$2:$J$116),D_CURV!$T$7) -> 35 | C21: =MAX(MAX(D_DAMP!$J$2:$J$155),D_DAMP!$T$7) -> 51 | D21: =MAX(MAX(D_ZEN!$J$2:$J$137),D_ZEN!$T$7) -> 61 | E21: =MAX(MAX(D_DRIP!$J$2:$J$128),D_DRIP!$T$7) -> 80 | F21: =MAX(MAX(D_DROT!$J$2:$J$122),D_DROT!$T$7) -> 182 | G21: =MAX(MAX(D_SKEW!$J$2:$J$236),D_SKEW!$T$7) -> 64 | H21: =MAX(MAX(D_SKEWTSL!$J$2:$J$237),D_SKEWTSL!$T$7) -> 76
A23: Excluding Wednesday (Wed P&L = 0)
A24: Metric | B24: Curvature | C24: Damper | D24: Zen | E24: Delta-Ripple | F24: Delta-Rotation | G24: SkewHunter | H24: SkewHunter TSL
A25: Type | B25: Credit | C25: Credit | D25: Credit | E25: Credit | F25: Credit | G25: Option | H25: Option
A26: Allocation (Rs) | B26: =D_CURV!$T$1 -> 320000 | C26: =D_DAMP!$T$1 -> 320000 | D26: =D_ZEN!$T$1 -> 320000 | E26: =D_DRIP!$T$1 -> 320000 | F26: =D_DROT!$T$1 -> 320000 | G26: =D_SKEW!$T$1 -> 500000 | H26: =D_SKEWTSL!$T$1 -> 500000
A27: Return 1M | B27: =SUMIFS(D_CURV!$K$2:$K$116,D_CURV!$A$2:$A$116,">="&D_CURV!$T$3)/D_CURV!$T$1*100 -> 35.781484 | C27: =SUMIFS(D_DAMP!$K$2:$K$155,D_DAMP!$A$2:$A$155,">="&D_DAMP!$T$3)/D_DAMP!$T$1*100 -> 12.875078 | D27: =SUMIFS(D_ZEN!$K$2:$K$137,D_ZEN!$A$2:$A$137,">="&D_ZEN!$T$3)/D_ZEN!$T$1*100 -> 12.282969 | E27: =SUMIFS(D_DRIP!$K$2:$K$128,D_DRIP!$A$2:$A$128,">="&D_DRIP!$T$3)/D_DRIP!$T$1*100 -> 30.381406 | F27: =SUMIFS(D_DROT!$K$2:$K$122,D_DROT!$A$2:$A$122,">="&D_DROT!$T$3)/D_DROT!$T$1*100 -> 14.883984 | G27: =SUMIFS(D_SKEW!$K$2:$K$236,D_SKEW!$A$2:$A$236,">="&D_SKEW!$T$3)/D_SKEW!$T$1*100 -> 23.946 | H27: =SUMIFS(D_SKEWTSL!$K$2:$K$237,D_SKEWTSL!$A$2:$A$237,">="&D_SKEWTSL!$T$3)/D_SKEWTSL!$T$1*100 -> 18.1428
A28: Return 3M | B28: =SUMIFS(D_CURV!$K$2:$K$116,D_CURV!$A$2:$A$116,">="&D_CURV!$T$4)/D_CURV!$T$1*100 -> 68.167734 | C28: =SUMIFS(D_DAMP!$K$2:$K$155,D_DAMP!$A$2:$A$155,">="&D_DAMP!$T$4)/D_DAMP!$T$1*100 -> 23.495469 | D28: =SUMIFS(D_ZEN!$K$2:$K$137,D_ZEN!$A$2:$A$137,">="&D_ZEN!$T$4)/D_ZEN!$T$1*100 -> 60.001094 | E28: =SUMIFS(D_DRIP!$K$2:$K$128,D_DRIP!$A$2:$A$128,">="&D_DRIP!$T$4)/D_DRIP!$T$1*100 -> 94.994453 | F28: =SUMIFS(D_DROT!$K$2:$K$122,D_DROT!$A$2:$A$122,">="&D_DROT!$T$4)/D_DROT!$T$1*100 -> 59.483125 | G28: =SUMIFS(D_SKEW!$K$2:$K$236,D_SKEW!$A$2:$A$236,">="&D_SKEW!$T$4)/D_SKEW!$T$1*100 -> 7.86955 | H28: =SUMIFS(D_SKEWTSL!$K$2:$K$237,D_SKEWTSL!$A$2:$A$237,">="&D_SKEWTSL!$T$4)/D_SKEWTSL!$T$1*100 -> 30.97835
A29: Return 6M | B29: =SUMIFS(D_CURV!$K$2:$K$116,D_CURV!$A$2:$A$116,">="&D_CURV!$T$5)/D_CURV!$T$1*100 -> 113.58734 | C29: =SUMIFS(D_DAMP!$K$2:$K$155,D_DAMP!$A$2:$A$155,">="&D_DAMP!$T$5)/D_DAMP!$T$1*100 -> 91.607422 | D29: =SUMIFS(D_ZEN!$K$2:$K$137,D_ZEN!$A$2:$A$137,">="&D_ZEN!$T$5)/D_ZEN!$T$1*100 -> 107.11773 | E29: =SUMIFS(D_DRIP!$K$2:$K$128,D_DRIP!$A$2:$A$128,">="&D_DRIP!$T$5)/D_DRIP!$T$1*100 -> 129.74129 | F29: =SUMIFS(D_DROT!$K$2:$K$122,D_DROT!$A$2:$A$122,">="&D_DROT!$T$5)/D_DROT!$T$1*100 -> 110.02059 | G29: =SUMIFS(D_SKEW!$K$2:$K$236,D_SKEW!$A$2:$A$236,">="&D_SKEW!$T$5)/D_SKEW!$T$1*100 -> 128.1837 | H29: =SUMIFS(D_SKEWTSL!$K$2:$K$237,D_SKEWTSL!$A$2:$A$237,">="&D_SKEWTSL!$T$5)/D_SKEWTSL!$T$1*100 -> 113.1809
A30: Return 1Y | B30: =SUMIFS(D_CURV!$K$2:$K$116,D_CURV!$A$2:$A$116,">="&D_CURV!$T$6)/D_CURV!$T$1*100 -> 209.94477 | C30: =SUMIFS(D_DAMP!$K$2:$K$155,D_DAMP!$A$2:$A$155,">="&D_DAMP!$T$6)/D_DAMP!$T$1*100 -> 129.14023 | D30: =SUMIFS(D_ZEN!$K$2:$K$137,D_ZEN!$A$2:$A$137,">="&D_ZEN!$T$6)/D_ZEN!$T$1*100 -> 184.85172 | E30: =SUMIFS(D_DRIP!$K$2:$K$128,D_DRIP!$A$2:$A$128,">="&D_DRIP!$T$6)/D_DRIP!$T$1*100 -> 171.75174 | F30: =SUMIFS(D_DROT!$K$2:$K$122,D_DROT!$A$2:$A$122,">="&D_DROT!$T$6)/D_DROT!$T$1*100 -> 126.21156 | G30: =SUMIFS(D_SKEW!$K$2:$K$236,D_SKEW!$A$2:$A$236,">="&D_SKEW!$T$6)/D_SKEW!$T$1*100 -> 361.08195 | H30: =SUMIFS(D_SKEWTSL!$K$2:$K$237,D_SKEWTSL!$A$2:$A$237,">="&D_SKEWTSL!$T$6)/D_SKEWTSL!$T$1*100 -> 237.43715
A31: Return Max | B31: =SUM(D_CURV!$K$2:$K$116)/D_CURV!$T$1*100 -> 209.94477 | C31: =SUM(D_DAMP!$K$2:$K$155)/D_DAMP!$T$1*100 -> 129.14023 | D31: =SUM(D_ZEN!$K$2:$K$137)/D_ZEN!$T$1*100 -> 184.85172 | E31: =SUM(D_DRIP!$K$2:$K$128)/D_DRIP!$T$1*100 -> 171.75174 | F31: =SUM(D_DROT!$K$2:$K$122)/D_DROT!$T$1*100 -> 126.21156 | G31: =SUM(D_SKEW!$K$2:$K$236)/D_SKEW!$T$1*100 -> 361.08195 | H31: =SUM(D_SKEWTSL!$K$2:$K$237)/D_SKEWTSL!$T$1*100 -> 237.43715
A32: Gross Gain (Rs) | B32: =SUM(D_CURV!$K$2:$K$116) -> 671823.25 | C32: =SUM(D_DAMP!$K$2:$K$155) -> 413248.75 | D32: =SUM(D_ZEN!$K$2:$K$137) -> 591525.5 | E32: =SUM(D_DRIP!$K$2:$K$128) -> 549605.58 | F32: =SUM(D_DROT!$K$2:$K$122) -> 403877 | G32: =SUM(D_SKEW!$K$2:$K$236) -> 1805409.8 | H32: =SUM(D_SKEWTSL!$K$2:$K$237) -> 1187185.8
A33: CAGR | B33: =((1+SUM(D_CURV!$K$2:$K$116)/D_CURV!$T$1)^(365/(D_CURV!$T$2-D_CURV!$T$9))-1)*100 -> 277.2139 | C33: =((1+SUM(D_DAMP!$K$2:$K$155)/D_DAMP!$T$1)^(365/(D_DAMP!$T$2-D_DAMP!$T$9))-1)*100 -> 224.65941 | D33: =((1+SUM(D_ZEN!$K$2:$K$137)/D_ZEN!$T$1)^(365/(D_ZEN!$T$2-D_ZEN!$T$9))-1)*100 -> 221.6986 | E33: =((1+SUM(D_DRIP!$K$2:$K$128)/D_DRIP!$T$1)^(365/(D_DRIP!$T$2-D_DRIP!$T$9))-1)*100 -> 186.21622 | F33: =((1+SUM(D_DROT!$K$2:$K$122)/D_DROT!$T$1)^(365/(D_DROT!$T$2-D_DROT!$T$9))-1)*100 -> 130.3876 | G33: =((1+SUM(D_SKEW!$K$2:$K$236)/D_SKEW!$T$1)^(365/(D_SKEW!$T$2-D_SKEW!$T$9))-1)*100 -> 363.02206 | H33: =((1+SUM(D_SKEWTSL!$K$2:$K$237)/D_SKEWTSL!$T$1)^(365/(D_SKEWTSL!$T$2-D_SKEWTSL!$T$9))-1)*100 -> 238.56649
A34: XIRR | B34: 838 | C34: 531.8 | D34: 611.7 | E34: 350.8 | F34: 171 | G34: 4699.5 | H34: 584.4
A35: Avg Drawdown | B35: =AVERAGE(D_CURV!$N$2:$N$116) -> -3.3157099 | C35: =AVERAGE(D_DAMP!$N$2:$N$155) -> -3.517289 | D35: =AVERAGE(D_ZEN!$N$2:$N$137) -> -4.9162868 | E35: =AVERAGE(D_DRIP!$N$2:$N$128) -> -6.4380029 | F35: =AVERAGE(D_DROT!$N$2:$N$122) -> -10.392809 | G35: =AVERAGE(D_SKEW!$N$2:$N$236) -> -13.637386 | H35: =AVERAGE(D_SKEWTSL!$N$2:$N$237) -> -16.084412
A36: Max Drawdown | B36: =MIN(D_CURV!$N$2:$N$116) -> -22.170078 | C36: =MIN(D_DAMP!$N$2:$N$155) -> -16.864453 | D36: =MIN(D_ZEN!$N$2:$N$137) -> -22.384375 | E36: =MIN(D_DRIP!$N$2:$N$128) -> -27.872625 | F36: =MIN(D_DROT!$N$2:$N$122) -> -34.2798 | G36: =MIN(D_SKEW!$N$2:$N$236) -> -51.34935 | H36: =MIN(D_SKEWTSL!$N$2:$N$237) -> -57.4305
A37: Success Ratio | B37: =COUNTIF(D_CURV!$K$2:$K$116,">0")/(COUNTIF(D_CURV!$K$2:$K$116,">0")+COUNTIF(D_CURV!$K$2:$K$116,"<0"))*100 -> 63.809524 | C37: =COUNTIF(D_DAMP!$K$2:$K$155,">0")/(COUNTIF(D_DAMP!$K$2:$K$155,">0")+COUNTIF(D_DAMP!$K$2:$K$155,"<0"))*100 -> 68 | D37: =COUNTIF(D_ZEN!$K$2:$K$137,">0")/(COUNTIF(D_ZEN!$K$2:$K$137,">0")+COUNTIF(D_ZEN!$K$2:$K$137,"<0"))*100 -> 63.636364 | E37: =COUNTIF(D_DRIP!$K$2:$K$128,">0")/(COUNTIF(D_DRIP!$K$2:$K$128,">0")+COUNTIF(D_DRIP!$K$2:$K$128,"<0"))*100 -> 58.333333 | F37: =COUNTIF(D_DROT!$K$2:$K$122,">0")/(COUNTIF(D_DROT!$K$2:$K$122,">0")+COUNTIF(D_DROT!$K$2:$K$122,"<0"))*100 -> 53.982301 | G37: =COUNTIF(D_SKEW!$K$2:$K$236,">0")/(COUNTIF(D_SKEW!$K$2:$K$236,">0")+COUNTIF(D_SKEW!$K$2:$K$236,"<0"))*100 -> 43.315508 | H37: =COUNTIF(D_SKEWTSL!$K$2:$K$237,">0")/(COUNTIF(D_SKEWTSL!$K$2:$K$237,">0")+COUNTIF(D_SKEWTSL!$K$2:$K$237,"<0"))*100 -> 42.553191
A38: Risk : Reward | B38: =AVERAGEIF(D_CURV!$K$2:$K$116,">0")/-AVERAGEIF(D_CURV!$K$2:$K$116,"<0") -> 1.2365475 | C38: =AVERAGEIF(D_DAMP!$K$2:$K$155,">0")/-AVERAGEIF(D_DAMP!$K$2:$K$155,"<0") -> 0.94839534 | D38: =AVERAGEIF(D_ZEN!$K$2:$K$137,">0")/-AVERAGEIF(D_ZEN!$K$2:$K$137,"<0") -> 1.0358053 | E38: =AVERAGEIF(D_DRIP!$K$2:$K$128,">0")/-AVERAGEIF(D_DRIP!$K$2:$K$128,"<0") -> 1.2583629 | F38: =AVERAGEIF(D_DROT!$K$2:$K$122,">0")/-AVERAGEIF(D_DROT!$K$2:$K$122,"<0") -> 1.2929661 | G38: =AVERAGEIF(D_SKEW!$K$2:$K$236,">0")/-AVERAGEIF(D_SKEW!$K$2:$K$236,"<0") -> 2.1760534 | H38: =AVERAGEIF(D_SKEWTSL!$K$2:$K$237,">0")/-AVERAGEIF(D_SKEWTSL!$K$2:$K$237,"<0") -> 2.0729441
A39: Avg Profit /day (Rs) | B39: =AVERAGEIF(D_CURV!$K$2:$K$116,">0") -> 18523.205 | C39: =AVERAGEIF(D_DAMP!$K$2:$K$155,">0") -> 9650.0471 | D39: =AVERAGEIF(D_ZEN!$K$2:$K$137,">0") -> 17135.25 | E39: =AVERAGEIF(D_DRIP!$K$2:$K$128,">0") -> 20176.97 | F39: =AVERAGEIF(D_DROT!$K$2:$K$122,">0") -> 19433.611 | G39: =AVERAGEIF(D_SKEW!$K$2:$K$236,">0") -> 55915.88 | H39: =AVERAGEIF(D_SKEWTSL!$K$2:$K$237,">0") -> 42551.175
A40: Avg Loss /day (Rs) | B40: =AVERAGEIF(D_CURV!$K$2:$K$116,"<0") -> -14979.776 | C40: =AVERAGEIF(D_DAMP!$K$2:$K$155,"<0") -> -10175.131 | D40: =AVERAGEIF(D_ZEN!$K$2:$K$137,"<0") -> -16542.926 | E40: =AVERAGEIF(D_DRIP!$K$2:$K$128,"<0") -> -16034.301 | F40: =AVERAGEIF(D_DROT!$K$2:$K$122,"<0") -> -15030.256 | G40: =AVERAGEIF(D_SKEW!$K$2:$K$236,"<0") -> -25696.005 | H40: =AVERAGEIF(D_SKEWTSL!$K$2:$K$237,"<0") -> -20526.928
A41: Avg Recovery (days) | B41: =AVERAGEIF(D_CURV!$Q$2:$Q$116,">0") -> 10.857143 | C41: =AVERAGEIF(D_DAMP!$Q$2:$Q$155,">0") -> 11.058824 | D41: =AVERAGEIF(D_ZEN!$Q$2:$Q$137,">0") -> 12.777778 | E41: =AVERAGEIF(D_DRIP!$Q$2:$Q$128,">0") -> 16.666667 | F41: =AVERAGEIF(D_DROT!$Q$2:$Q$122,">0") -> 27.090909 | G41: =AVERAGEIF(D_SKEW!$Q$2:$Q$236,">0") -> 12.333333 | H41: =AVERAGEIF(D_SKEWTSL!$Q$2:$Q$237,">0") -> 17.473684
...

Sheet Individual - Day of Week
A1: Statistics B — Day-of-Week Performance (Individual Algos)
A3: Curvature
A4: Weekday | B4: Success % | C4: Avg Profit (Rs) | D4: Max Profit (Rs) | E4: Avg Loss (Rs) | F4: Max Loss (Rs) | G4: Total P&L (Rs) | H4: # Days
A5: Monday | B5: =IFERROR(COUNTIFS(D_CURV!$B$2:$B$116,"Monday",D_CURV!$C$2:$C$116,">0")/(COUNTIFS(D_CURV!$B$2:$B$116,"Monday",D_CURV!$C$2:$C$116,">0")+COUNTIFS(D_CURV!$B$2:$B$116,"Monday",D_CURV!$C$2:$C$116,"<0"))*100,0) -> 57.692308 | C5: =IFERROR(AVERAGEIFS(D_CURV!$C$2:$C$116,D_CURV!$B$2:$B$116,"Monday",D_CURV!$C$2:$C$116,">0"),0) -> 21239.867 | D5: {=MAX(IF(D_CURV!$B$2:$B$116="Monday",D_CURV!$C$2:$C$116))} -> 41275 | E5: =IFERROR(AVERAGEIFS(D_CURV!$C$2:$C$116,D_CURV!$B$2:$B$116,"Monday",D_CURV!$C$2:$C$116,"<0"),0) -> -20909.886 | F5: {=MIN(IF(D_CURV!$B$2:$B$116="Monday",D_CURV!$C$2:$C$116))} -> -47326.5 | G5: =SUMIFS(D_CURV!$C$2:$C$116,D_CURV!$B$2:$B$116,"Monday") -> 88589.25 | H5: =COUNTIF(D_CURV!$B$2:$B$116,"Monday") -> 26
A6: Tuesday | B6: =IFERROR(COUNTIFS(D_CURV!$B$2:$B$116,"Tuesday",D_CURV!$C$2:$C$116,">0")/(COUNTIFS(D_CURV!$B$2:$B$116,"Tuesday",D_CURV!$C$2:$C$116,">0")+COUNTIFS(D_CURV!$B$2:$B$116,"Tuesday",D_CURV!$C$2:$C$116,"<0"))*100,0) -> 76.666667 | C6: =IFERROR(AVERAGEIFS(D_CURV!$C$2:$C$116,D_CURV!$B$2:$B$116,"Tuesday",D_CURV!$C$2:$C$116,">0"),0) -> 16486.87 | D6: {=MAX(IF(D_CURV!$B$2:$B$116="Tuesday",D_CURV!$C$2:$C$116))} -> 35445 | E6: =IFERROR(AVERAGEIFS(D_CURV!$C$2:$C$116,D_CURV!$B$2:$B$116,"Tuesday",D_CURV!$C$2:$C$116,"<0"),0) -> -9321.4286 | F6: {=MIN(IF(D_CURV!$B$2:$B$116="Tuesday",D_CURV!$C$2:$C$116))} -> -14085 | G6: =SUMIFS(D_CURV!$C$2:$C$116,D_CURV!$B$2:$B$116,"Tuesday") -> 313948 | H6: =COUNTIF(D_CURV!$B$2:$B$116,"Tuesday") -> 30
A7: Wednesday | B7: =IFERROR(COUNTIFS(D_CURV!$B$2:$B$116,"Wednesday",D_CURV!$C$2:$C$116,">0")/(COUNTIFS(D_CURV!$B$2:$B$116,"Wednesday",D_CURV!$C$2:$C$116,">0")+COUNTIFS(D_CURV!$B$2:$B$116,"Wednesday",D_CURV!$C$2:$C$116,"<0"))*100,0) -> 20 | C7: =IFERROR(AVERAGEIFS(D_CURV!$C$2:$C$116,D_CURV!$B$2:$B$116,"Wednesday",D_CURV!$C$2:$C$116,">0"),0) -> 13650 | D7: {=MAX(IF(D_CURV!$B$2:$B$116="Wednesday",D_CURV!$C$2:$C$116))} -> 15750 | E7: =IFERROR(AVERAGEIFS(D_CURV!$C$2:$C$116,D_CURV!$B$2:$B$116,"Wednesday",D_CURV!$C$2:$C$116,"<0"),0) -> -14077.188 | F7: {=MIN(IF(D_CURV!$B$2:$B$116="Wednesday",D_CURV!$C$2:$C$116))} -> -27738.75 | G7: =SUMIFS(D_CURV!$C$2:$C$116,D_CURV!$B$2:$B$116,"Wednesday") -> -85317.5 | H7: =COUNTIF(D_CURV!$B$2:$B$116,"Wednesday") -> 10
A8: Thursday | B8: =IFERROR(COUNTIFS(D_CURV!$B$2:$B$116,"Thursday",D_CURV!$C$2:$C$116,">0")/(COUNTIFS(D_CURV!$B$2:$B$116,"Thursday",D_CURV!$C$2:$C$116,">0")+COUNTIFS(D_CURV!$B$2:$B$116,"Thursday",D_CURV!$C$2:$C$116,"<0"))*100,0) -> 44 | C8: =IFERROR(AVERAGEIFS(D_CURV!$C$2:$C$116,D_CURV!$B$2:$B$116,"Thursday",D_CURV!$C$2:$C$116,">0"),0) -> 19912.386 | D8: {=MAX(IF(D_CURV!$B$2:$B$116="Thursday",D_CURV!$C$2:$C$116))} -> 41145 | E8: =IFERROR(AVERAGEIFS(D_CURV!$C$2:$C$116,D_CURV!$B$2:$B$116,"Thursday",D_CURV!$C$2:$C$116,"<0"),0) -> -13781.946 | F8: {=MIN(IF(D_CURV!$B$2:$B$116="Thursday",D_CURV!$C$2:$C$116))} -> -27780 | G8: =SUMIFS(D_CURV!$C$2:$C$116,D_CURV!$B$2:$B$116,"Thursday") -> 26089 | H8: =COUNTIF(D_CURV!$B$2:$B$116,"Thursday") -> 25
A9: Friday | B9: =IFERROR(COUNTIFS(D_CURV!$B$2:$B$116,"Friday",D_CURV!$C$2:$C$116,">0")/(COUNTIFS(D_CURV!$B$2:$B$116,"Friday",D_CURV!$C$2:$C$116,">0")+COUNTIFS(D_CURV!$B$2:$B$116,"Friday",D_CURV!$C$2:$C$116,"<0"))*100,0) -> 75 | C9: =IFERROR(AVERAGEIFS(D_CURV!$C$2:$C$116,D_CURV!$B$2:$B$116,"Friday",D_CURV!$C$2:$C$116,">0"),0) -> 18012.361 | D9: {=MAX(IF(D_CURV!$B$2:$B$116="Friday",D_CURV!$C$2:$C$116))} -> 43350 | E9: =IFERROR(AVERAGEIFS(D_CURV!$C$2:$C$116,D_CURV!$B$2:$B$116,"Friday",D_CURV!$C$2:$C$116,"<0"),0) -> -13504.25 | F9: {=MIN(IF(D_CURV!$B$2:$B$116="Friday",D_CURV!$C$2:$C$116))} -> -18115.5 | G9: =SUMIFS(D_CURV!$C$2:$C$116,D_CURV!$B$2:$B$116,"Friday") -> 243197 | H9: =COUNTIF(D_CURV!$B$2:$B$116,"Friday") -> 24
A10: Best day (incl Wed) | B10: =INDEX($A$5:$A$9,MATCH(MAX($G$5:$G$9),$G$5:$G$9,0)) -> Tuesday | D10: Best day (excl Wed) | E10: =INDEX($A$5:$A$9,MATCH(MAX($G$5:$G$6,$G$8:$G$9),$G$5:$G$9,0)) -> Tuesday
A12: Damper
A13: Weekday | B13: Success % | C13: Avg Profit (Rs) | D13: Max Profit (Rs) | E13: Avg Loss (Rs) | F13: Max Loss (Rs) | G13: Total P&L (Rs) | H13: # Days
A14: Monday | B14: =IFERROR(COUNTIFS(D_DAMP!$B$2:$B$155,"Monday",D_DAMP!$C$2:$C$155,">0")/(COUNTIFS(D_DAMP!$B$2:$B$155,"Monday",D_DAMP!$C$2:$C$155,">0")+COUNTIFS(D_DAMP!$B$2:$B$155,"Monday",D_DAMP!$C$2:$C$155,"<0"))*100,0) -> 67.647059 | C14: =IFERROR(AVERAGEIFS(D_DAMP!$C$2:$C$155,D_DAMP!$B$2:$B$155,"Monday",D_DAMP!$C$2:$C$155,">0"),0) -> 8521.0326 | D14: {=MAX(IF(D_DAMP!$B$2:$B$155="Monday",D_DAMP!$C$2:$C$155))} -> 21827 | E14: =IFERROR(AVERAGEIFS(D_DAMP!$C$2:$C$155,D_DAMP!$B$2:$B$155,"Monday",D_DAMP!$C$2:$C$155,"<0"),0) -> -7802.0227 | F14: {=MIN(IF(D_DAMP!$B$2:$B$155="Monday",D_DAMP!$C$2:$C$155))} -> -18746 | G14: =SUMIFS(D_DAMP!$C$2:$C$155,D_DAMP!$B$2:$B$155,"Monday") -> 110161.5 | H14: =COUNTIF(D_DAMP!$B$2:$B$155,"Monday") -> 34
A15: Tuesday | B15: =IFERROR(COUNTIFS(D_DAMP!$B$2:$B$155,"Tuesday",D_DAMP!$C$2:$C$155,">0")/(COUNTIFS(D_DAMP!$B$2:$B$155,"Tuesday",D_DAMP!$C$2:$C$155,">0")+COUNTIFS(D_DAMP!$B$2:$B$155,"Tuesday",D_DAMP!$C$2:$C$155,"<0"))*100,0) -> 66.666667 | C15: =IFERROR(AVERAGEIFS(D_DAMP!$C$2:$C$155,D_DAMP!$B$2:$B$155,"Tuesday",D_DAMP!$C$2:$C$155,">0"),0) -> 7694.475 | D15: {=MAX(IF(D_DAMP!$B$2:$B$155="Tuesday",D_DAMP!$C$2:$C$155))} -> 14547 | E15: =IFERROR(AVERAGEIFS(D_DAMP!$C$2:$C$155,D_DAMP!$B$2:$B$155,"Tuesday",D_DAMP!$C$2:$C$155,"<0"),0) -> -8398.725 | F15: {=MIN(IF(D_DAMP!$B$2:$B$155="Tuesday",D_DAMP!$C$2:$C$155))} -> -10140 | G15: =SUMIFS(D_DAMP!$C$2:$C$155,D_DAMP!$B$2:$B$155,"Tuesday") -> 69902.25 | H15: =COUNTIF(D_DAMP!$B$2:$B$155,"Tuesday") -> 30
A16: Wednesday | B16: =IFERROR(COUNTIFS(D_DAMP!$B$2:$B$155,"Wednesday",D_DAMP!$C$2:$C$155,">0")/(COUNTIFS(D_DAMP!$B$2:$B$155,"Wednesday",D_DAMP!$C$2:$C$155,">0")+COUNTIFS(D_DAMP!$B$2:$B$155,"Wednesday",D_DAMP!$C$2:$C$155,"<0"))*100,0) -> 48.275862 | C16: =IFERROR(AVERAGEIFS(D_DAMP!$C$2:$C$155,D_DAMP!$B$2:$B$155,"Wednesday",D_DAMP!$C$2:$C$155,">0"),0) -> 7845.3571 | D16: {=MAX(IF(D_DAMP!$B$2:$B$155="Wednesday",D_DAMP!$C$2:$C$155))} -> 25087.5 | E16: =IFERROR(AVERAGEIFS(D_DAMP!$C$2:$C$155,D_DAMP!$B$2:$B$155,"Wednesday",D_DAMP!$C$2:$C$155,"<0"),0) -> -10420.583 | F16: {=MIN(IF(D_DAMP!$B$2:$B$155="Wednesday",D_DAMP!$C$2:$C$155))} -> -36400 | G16: =SUMIFS(D_DAMP!$C$2:$C$155,D_DAMP!$B$2:$B$155,"Wednesday") -> -46473.75 | H16: =COUNTIF(D_DAMP!$B$2:$B$155,"Wednesday") -> 29
A17: Thursday | B17: =IFERROR(COUNTIFS(D_DAMP!$B$2:$B$155,"Thursday",D_DAMP!$C$2:$C$155,">0")/(COUNTIFS(D_DAMP!$B$2:$B$155,"Thursday",D_DAMP!$C$2:$C$155,">0")+COUNTIFS(D_DAMP!$B$2:$B$155,"Thursday",D_DAMP!$C$2:$C$155,"<0"))*100,0) -> 65.517241 | C17: =IFERROR(AVERAGEIFS(D_DAMP!$C$2:$C$155,D_DAMP!$B$2:$B$155,"Thursday",D_DAMP!$C$2:$C$155,">0"),0) -> 11661.316 | D17: {=MAX(IF(D_DAMP!$B$2:$B$155="Thursday",D_DAMP!$C$2:$C$155))} -> 24098.75 | E17: =IFERROR(AVERAGEIFS(D_DAMP!$C$2:$C$155,D_DAMP!$B$2:$B$155,"Thursday",D_DAMP!$C$2:$C$155,"<0"),0) -> -9899.825 | F17: {=MIN(IF(D_DAMP!$B$2:$B$155="Thursday",D_DAMP!$C$2:$C$155))} -> -17306.25 | G17: =SUMIFS(D_DAMP!$C$2:$C$155,D_DAMP!$B$2:$B$155,"Thursday") -> 122566.75 | H17: =COUNTIF(D_DAMP!$B$2:$B$155,"Thursday") -> 29
A18: Friday | B18: =IFERROR(COUNTIFS(D_DAMP!$B$2:$B$155,"Friday",D_DAMP!$C$2:$C$155,">0")/(COUNTIFS(D_DAMP!$B$2:$B$155,"Friday",D_DAMP!$C$2:$C$155,">0")+COUNTIFS(D_DAMP!$B$2:$B$155,"Friday",D_DAMP!$C$2:$C$155,"<0"))*100,0) -> 71.875 | C18: =IFERROR(AVERAGEIFS(D_DAMP!$C$2:$C$155,D_DAMP!$B$2:$B$155,"Friday",D_DAMP!$C$2:$C$155,">0"),0) -> 10818.076 | D18: {=MAX(IF(D_DAMP!$B$2:$B$155="Friday",D_DAMP!$C$2:$C$155))} -> 27657.5 | E18: =IFERROR(AVERAGEIFS(D_DAMP!$C$2:$C$155,D_DAMP!$B$2:$B$155,"Friday",D_DAMP!$C$2:$C$155,"<0"),0) -> -15355.278 | F18: {=MIN(IF(D_DAMP!$B$2:$B$155="Friday",D_DAMP!$C$2:$C$155))} -> -28395 | G18: =SUMIFS(D_DAMP!$C$2:$C$155,D_DAMP!$B$2:$B$155,"Friday") -> 110618.25 | H18: =COUNTIF(D_DAMP!$B$2:$B$155,"Friday") -> 32
A19: Best day (incl Wed) | B19: =INDEX($A$14:$A$18,MATCH(MAX($G$14:$G$18),$G$14:$G$18,0)) -> Thursday | D19: Best day (excl Wed) | E19: =INDEX($A$14:$A$18,MATCH(MAX($G$14:$G$15,$G$17:$G$18),$G$14:$G$18,0)) -> Thursday
A21: Zen
A22: Weekday | B22: Success % | C22: Avg Profit (Rs) | D22: Max Profit (Rs) | E22: Avg Loss (Rs) | F22: Max Loss (Rs) | G22: Total P&L (Rs) | H22: # Days
A23: Monday | B23: =IFERROR(COUNTIFS(D_ZEN!$B$2:$B$137,"Monday",D_ZEN!$C$2:$C$137,">0")/(COUNTIFS(D_ZEN!$B$2:$B$137,"Monday",D_ZEN!$C$2:$C$137,">0")+COUNTIFS(D_ZEN!$B$2:$B$137,"Monday",D_ZEN!$C$2:$C$137,"<0"))*100,0) -> 67.647059 | C23: =IFERROR(AVERAGEIFS(D_ZEN!$C$2:$C$137,D_ZEN!$B$2:$B$137,"Monday",D_ZEN!$C$2:$C$137,">0"),0) -> 18654.424 | D23: {=MAX(IF(D_ZEN!$B$2:$B$137="Monday",D_ZEN!$C$2:$C$137))} -> 41827.5 | E23: =IFERROR(AVERAGEIFS(D_ZEN!$C$2:$C$137,D_ZEN!$B$2:$B$137,"Monday",D_ZEN!$C$2:$C$137,"<0"),0) -> -24836.136 | F23: {=MIN(IF(D_ZEN!$B$2:$B$137="Monday",D_ZEN!$C$2:$C$137))} -> -65503.75 | G23: =SUMIFS(D_ZEN!$C$2:$C$137,D_ZEN!$B$2:$B$137,"Monday") -> 155854.25 | H23: =COUNTIF(D_ZEN!$B$2:$B$137,"Monday") -> 34
A24: Tuesday | B24: =IFERROR(COUNTIFS(D_ZEN!$B$2:$B$137,"Tuesday",D_ZEN!$C$2:$C$137,">0")/(COUNTIFS(D_ZEN!$B$2:$B$137,"Tuesday",D_ZEN!$C$2:$C$137,">0")+COUNTIFS(D_ZEN!$B$2:$B$137,"Tuesday",D_ZEN!$C$2:$C$137,"<0"))*100,0) -> 75.757576 | C24: =IFERROR(AVERAGEIFS(D_ZEN!$C$2:$C$137,D_ZEN!$B$2:$B$137,"Tuesday",D_ZEN!$C$2:$C$137,">0"),0) -> 16558.95 | D24: {=MAX(IF(D_ZEN!$B$2:$B$137="Tuesday",D_ZEN!$C$2:$C$137))} -> 35055 | E24: =IFERROR(AVERAGEIFS(D_ZEN!$C$2:$C$137,D_ZEN!$B$2:$B$137,"Tuesday",D_ZEN!$C$2:$C$137,"<0"),0) -> -8082.6562 | F24: {=MIN(IF(D_ZEN!$B$2:$B$137="Tuesday",D_ZEN!$C$2:$C$137))} -> -14310 | G24: =SUMIFS(D_ZEN!$C$2:$C$137,D_ZEN!$B$2:$B$137,"Tuesday") -> 349312.5 | H24: =COUNTIF(D_ZEN!$B$2:$B$137,"Tuesday") -> 33
A25: Wednesday | B25: =IFERROR(COUNTIFS(D_ZEN!$B$2:$B$137,"Wednesday",D_ZEN!$C$2:$C$137,">0")/(COUNTIFS(D_ZEN!$B$2:$B$137,"Wednesday",D_ZEN!$C$2:$C$137,">0")+COUNTIFS(D_ZEN!$B$2:$B$137,"Wednesday",D_ZEN!$C$2:$C$137,"<0"))*100,0) -> 46.666667 | C25: =IFERROR(AVERAGEIFS(D_ZEN!$C$2:$C$137,D_ZEN!$B$2:$B$137,"Wednesday",D_ZEN!$C$2:$C$137,">0"),0) -> 10188.214 | D25: {=MAX(IF(D_ZEN!$B$2:$B$137="Wednesday",D_ZEN!$C$2:$C$137))} -> 15420 | E25: =IFERROR(AVERAGEIFS(D_ZEN!$C$2:$C$137,D_ZEN!$B$2:$B$137,"Wednesday",D_ZEN!$C$2:$C$137,"<0"),0) -> -17409.531 | F25: {=MIN(IF(D_ZEN!$B$2:$B$137="Wednesday",D_ZEN!$C$2:$C$137))} -> -37180 | G25: =SUMIFS(D_ZEN!$C$2:$C$137,D_ZEN!$B$2:$B$137,"Wednesday") -> -67958.75 | H25: =COUNTIF(D_ZEN!$B$2:$B$137,"Wednesday") -> 15
A26: Thursday | B26: =IFERROR(COUNTIFS(D_ZEN!$B$2:$B$137,"Thursday",D_ZEN!$C$2:$C$137,">0")/(COUNTIFS(D_ZEN!$B$2:$B$137,"Thursday",D_ZEN!$C$2:$C$137,">0")+COUNTIFS(D_ZEN!$B$2:$B$137,"Thursday",D_ZEN!$C$2:$C$137,"<0"))*100,0) -> 64.516129 | C26: =IFERROR(AVERAGEIFS(D_ZEN!$C$2:$C$137,D_ZEN!$B$2:$B$137,"Thursday",D_ZEN!$C$2:$C$137,">0"),0) -> 16202.25 | D26: {=MAX(IF(D_ZEN!$B$2:$B$137="Thursday",D_ZEN!$C$2:$C$137))} -> 40950 | E26: =IFERROR(AVERAGEIFS(D_ZEN!$C$2:$C$137,D_ZEN!$B$2:$B$137,"Thursday",D_ZEN!$C$2:$C$137,"<0"),0) -> -16916.023 | F26: {=MIN(IF(D_ZEN!$B$2:$B$137="Thursday",D_ZEN!$C$2:$C$137))} -> -34190 | G26: =SUMIFS(D_ZEN!$C$2:$C$137,D_ZEN!$B$2:$B$137,"Thursday") -> 137968.75 | H26: =COUNTIF(D_ZEN!$B$2:$B$137,"Thursday") -> 31
A27: Friday | B27: =IFERROR(COUNTIFS(D_ZEN!$B$2:$B$137,"Friday",D_ZEN!$C$2:$C$137,">0")/(COUNTIFS(D_ZEN!$B$2:$B$137,"Friday",D_ZEN!$C$2:$C$137,">0")+COUNTIFS(D_ZEN!$B$2:$B$137,"Friday",D_ZEN!$C$2:$C$137,"<0"))*100,0) -> 39.130435 | C27: =IFERROR(AVERAGEIFS(D_ZEN!$C$2:$C$137,D_ZEN!$B$2:$B$137,"Friday",D_ZEN!$C$2:$C$137,">0"),0) -> 16927.083 | D27: {=MAX(IF(D_ZEN!$B$2:$B$137="Friday",D_ZEN!$C$2:$C$137))} -> 39150 | E27: =IFERROR(AVERAGEIFS(D_ZEN!$C$2:$C$137,D_ZEN!$B$2:$B$137,"Friday",D_ZEN!$C$2:$C$137,"<0"),0) -> -14568.125 | F27: {=MIN(IF(D_ZEN!$B$2:$B$137="Friday",D_ZEN!$C$2:$C$137))} -> -28095 | G27: =SUMIFS(D_ZEN!$C$2:$C$137,D_ZEN!$B$2:$B$137,"Friday") -> -51610 | H27: =COUNTIF(D_ZEN!$B$2:$B$137,"Friday") -> 23
A28: Best day (incl Wed) | B28: =INDEX($A$23:$A$27,MATCH(MAX($G$23:$G$27),$G$23:$G$27,0)) -> Tuesday | D28: Best day (excl Wed) | E28: =INDEX($A$23:$A$27,MATCH(MAX($G$23:$G$24,$G$26:$G$27),$G$23:$G$27,0)) -> Tuesday
A30: Delta-Ripple
A31: Weekday | B31: Success % | C31: Avg Profit (Rs) | D31: Max Profit (Rs) | E31: Avg Loss (Rs) | F31: Max Loss (Rs) | G31: Total P&L (Rs) | H31: # Days
A32: Monday | B32: =IFERROR(COUNTIFS(D_DRIP!$B$2:$B$128,"Monday",D_DRIP!$C$2:$C$128,">0")/(COUNTIFS(D_DRIP!$B$2:$B$128,"Monday",D_DRIP!$C$2:$C$128,">0")+COUNTIFS(D_DRIP!$B$2:$B$128,"Monday",D_DRIP!$C$2:$C$128,"<0"))*100,0) -> 61.538462 | C32: =IFERROR(AVERAGEIFS(D_DRIP!$C$2:$C$128,D_DRIP!$B$2:$B$128,"Monday",D_DRIP!$C$2:$C$128,">0"),0) -> 20464.395 | D32: {=MAX(IF(D_DRIP!$B$2:$B$128="Monday",D_DRIP!$C$2:$C$128))} -> 50066.25 | E32: =IFERROR(AVERAGEIFS(D_DRIP!$C$2:$C$128,D_DRIP!$B$2:$B$128,"Monday",D_DRIP!$C$2:$C$128,"<0"),0) -> -14624.059 | F32: {=MIN(IF(D_DRIP!$B$2:$B$128="Monday",D_DRIP!$C$2:$C$128))} -> -32516.25 | G32: =SUMIFS(D_DRIP!$C$2:$C$128,D_DRIP!$B$2:$B$128,"Monday") -> 271784.6 | H32: =COUNTIF(D_DRIP!$B$2:$B$128,"Monday") -> 39
A33: Tuesday | B33: =IFERROR(COUNTIFS(D_DRIP!$B$2:$B$128,"Tuesday",D_DRIP!$C$2:$C$128,">0")/(COUNTIFS(D_DRIP!$B$2:$B$128,"Tuesday",D_DRIP!$C$2:$C$128,">0")+COUNTIFS(D_DRIP!$B$2:$B$128,"Tuesday",D_DRIP!$C$2:$C$128,"<0"))*100,0) -> 52.380952 | C33: =IFERROR(AVERAGEIFS(D_DRIP!$C$2:$C$128,D_DRIP!$B$2:$B$128,"Tuesday",D_DRIP!$C$2:$C$128,">0"),0) -> 24778.897 | D33: {=MAX(IF(D_DRIP!$B$2:$B$128="Tuesday",D_DRIP!$C$2:$C$128))} -> 32344 | E33: =IFERROR(AVERAGEIFS(D_DRIP!$C$2:$C$128,D_DRIP!$B$2:$B$128,"Tuesday",D_DRIP!$C$2:$C$128,"<0"),0) -> -14760.175 | F33: {=MIN(IF(D_DRIP!$B$2:$B$128="Tuesday",D_DRIP!$C$2:$C$128))} -> -20462 | G33: =SUMIFS(D_DRIP!$C$2:$C$128,D_DRIP!$B$2:$B$128,"Tuesday") -> 124966.12 | H33: =COUNTIF(D_DRIP!$B$2:$B$128,"Tuesday") -> 21
A34: Wednesday | B34: =IFERROR(COUNTIFS(D_DRIP!$B$2:$B$128,"Wednesday",D_DRIP!$C$2:$C$128,">0")/(COUNTIFS(D_DRIP!$B$2:$B$128,"Wednesday",D_DRIP!$C$2:$C$128,">0")+COUNTIFS(D_DRIP!$B$2:$B$128,"Wednesday",D_DRIP!$C$2:$C$128,"<0"))*100,0) -> 36.842105 | C34: =IFERROR(AVERAGEIFS(D_DRIP!$C$2:$C$128,D_DRIP!$B$2:$B$128,"Wednesday",D_DRIP!$C$2:$C$128,">0"),0) -> 15731.169 | D34: {=MAX(IF(D_DRIP!$B$2:$B$128="Wednesday",D_DRIP!$C$2:$C$128))} -> 23447.68 | E34: =IFERROR(AVERAGEIFS(D_DRIP!$C$2:$C$128,D_DRIP!$B$2:$B$128,"Wednesday",D_DRIP!$C$2:$C$128,"<0"),0) -> -16710.879 | F34: {=MIN(IF(D_DRIP!$B$2:$B$128="Wednesday",D_DRIP!$C$2:$C$128))} -> -31294.95 | G34: =SUMIFS(D_DRIP!$C$2:$C$128,D_DRIP!$B$2:$B$128,"Wednesday") -> -90412.37 | H34: =COUNTIF(D_DRIP!$B$2:$B$128,"Wednesday") -> 19
A35: Thursday | B35: =IFERROR(COUNTIFS(D_DRIP!$B$2:$B$128,"Thursday",D_DRIP!$C$2:$C$128,">0")/(COUNTIFS(D_DRIP!$B$2:$B$128,"Thursday",D_DRIP!$C$2:$C$128,">0")+COUNTIFS(D_DRIP!$B$2:$B$128,"Thursday",D_DRIP!$C$2:$C$128,"<0"))*100,0) -> 77.777778 | C35: =IFERROR(AVERAGEIFS(D_DRIP!$C$2:$C$128,D_DRIP!$B$2:$B$128,"Thursday",D_DRIP!$C$2:$C$128,">0"),0) -> 19058.833 | D35: {=MAX(IF(D_DRIP!$B$2:$B$128="Thursday",D_DRIP!$C$2:$C$128))} -> 33751.25 | E35: =IFERROR(AVERAGEIFS(D_DRIP!$C$2:$C$128,D_DRIP!$B$2:$B$128,"Thursday",D_DRIP!$C$2:$C$128,"<0"),0) -> -15698.405 | F35: {=MIN(IF(D_DRIP!$B$2:$B$128="Thursday",D_DRIP!$C$2:$C$128))} -> -35589.96 | G35: =SUMIFS(D_DRIP!$C$2:$C$128,D_DRIP!$B$2:$B$128,"Thursday") -> 306045.06 | H35: =COUNTIF(D_DRIP!$B$2:$B$128,"Thursday") -> 27
A36: Friday | B36: =IFERROR(COUNTIFS(D_DRIP!$B$2:$B$128,"Friday",D_DRIP!$C$2:$C$128,">0")/(COUNTIFS(D_DRIP!$B$2:$B$128,"Friday",D_DRIP!$C$2:$C$128,">0")+COUNTIFS(D_DRIP!$B$2:$B$128,"Friday",D_DRIP!$C$2:$C$128,"<0"))*100,0) -> 35 | C36: =IFERROR(AVERAGEIFS(D_DRIP!$C$2:$C$128,D_DRIP!$B$2:$B$128,"Friday",D_DRIP!$C$2:$C$128,">0"),0) -> 15314.324 | D36: {=MAX(IF(D_DRIP!$B$2:$B$128="Friday",D_DRIP!$C$2:$C$128))} -> 28161.25 | E36: =IFERROR(AVERAGEIFS(D_DRIP!$C$2:$C$128,D_DRIP!$B$2:$B$128,"Friday",D_DRIP!$C$2:$C$128,"<0"),0) -> -15651.312 | F36: {=MIN(IF(D_DRIP!$B$2:$B$128="Friday",D_DRIP!$C$2:$C$128))} -> -38242.07 | G36: =SUMIFS(D_DRIP!$C$2:$C$128,D_DRIP!$B$2:$B$128,"Friday") -> -96266.79 | H36: =COUNTIF(D_DRIP!$B$2:$B$128,"Friday") -> 20
A37: Best day (incl Wed) | B37: =INDEX($A$32:$A$36,MATCH(MAX($G$32:$G$36),$G$32:$G$36,0)) -> Thursday | D37: Best day (excl Wed) | E37: =INDEX($A$32:$A$36,MATCH(MAX($G$32:$G$33,$G$35:$G$36),$G$32:$G$36,0)) -> Thursday
A39: Delta-Rotation
A40: Weekday | B40: Success % | C40: Avg Profit (Rs) | D40: Max Profit (Rs) | E40: Avg Loss (Rs) | F40: Max Loss (Rs) | G40: Total P&L (Rs) | H40: # Days
A41: Monday | B41: =IFERROR(COUNTIFS(D_DROT!$B$2:$B$122,"Monday",D_DROT!$C$2:$C$122,">0")/(COUNTIFS(D_DROT!$B$2:$B$122,"Monday",D_DROT!$C$2:$C$122,">0")+COUNTIFS(D_DROT!$B$2:$B$122,"Monday",D_DROT!$C$2:$C$122,"<0"))*100,0) -> 33.333333 | C41: =IFERROR(AVERAGEIFS(D_DROT!$C$2:$C$122,D_DROT!$B$2:$B$122,"Monday",D_DROT!$C$2:$C$122,">0"),0) -> 14310.737 | D41: {=MAX(IF(D_DROT!$B$2:$B$122="Monday",D_DROT!$C$2:$C$122))} -> 39081.25 | E41: =IFERROR(AVERAGEIFS(D_DROT!$C$2:$C$122,D_DROT!$B$2:$B$122,"Monday",D_DROT!$C$2:$C$122,"<0"),0) -> -15783.98 | F41: {=MIN(IF(D_DROT!$B$2:$B$122="Monday",D_DROT!$C$2:$C$122))} -> -47034 | G41: =SUMIFS(D_DROT!$C$2:$C$122,D_DROT!$B$2:$B$122,"Monday") -> -155315.01 | H41: =COUNTIF(D_DROT!$B$2:$B$122,"Monday") -> 27
A42: Tuesday | B42: =IFERROR(COUNTIFS(D_DROT!$B$2:$B$122,"Tuesday",D_DROT!$C$2:$C$122,">0")/(COUNTIFS(D_DROT!$B$2:$B$122,"Tuesday",D_DROT!$C$2:$C$122,">0")+COUNTIFS(D_DROT!$B$2:$B$122,"Tuesday",D_DROT!$C$2:$C$122,"<0"))*100,0) -> 78.571429 | C42: =IFERROR(AVERAGEIFS(D_DROT!$C$2:$C$122,D_DROT!$B$2:$B$122,"Tuesday",D_DROT!$C$2:$C$122,">0"),0) -> 21694.22 | D42: {=MAX(IF(D_DROT!$B$2:$B$122="Tuesday",D_DROT!$C$2:$C$122))} -> 51187.5 | E42: =IFERROR(AVERAGEIFS(D_DROT!$C$2:$C$122,D_DROT!$B$2:$B$122,"Tuesday",D_DROT!$C$2:$C$122,"<0"),0) -> -11340.417 | F42: {=MIN(IF(D_DROT!$B$2:$B$122="Tuesday",D_DROT!$C$2:$C$122))} -> -16103.75 | G42: =SUMIFS(D_DROT!$C$2:$C$122,D_DROT!$B$2:$B$122,"Tuesday") -> 409230.35 | H42: =COUNTIF(D_DROT!$B$2:$B$122,"Tuesday") -> 28
A43: Wednesday | B43: =IFERROR(COUNTIFS(D_DROT!$B$2:$B$122,"Wednesday",D_DROT!$C$2:$C$122,">0")/(COUNTIFS(D_DROT!$B$2:$B$122,"Wednesday",D_DROT!$C$2:$C$122,">0")+COUNTIFS(D_DROT!$B$2:$B$122,"Wednesday",D_DROT!$C$2:$C$122,"<0"))*100,0) -> 25 | C43: =IFERROR(AVERAGEIFS(D_DROT!$C$2:$C$122,D_DROT!$B$2:$B$122,"Wednesday",D_DROT!$C$2:$C$122,">0"),0) -> 7644.84 | D43: {=MAX(IF(D_DROT!$B$2:$B$122="Wednesday",D_DROT!$C$2:$C$122))} -> 8385.36 | E43: =IFERROR(AVERAGEIFS(D_DROT!$C$2:$C$122,D_DROT!$B$2:$B$122,"Wednesday",D_DROT!$C$2:$C$122,"<0"),0) -> -13839.758 | F43: {=MIN(IF(D_DROT!$B$2:$B$122="Wednesday",D_DROT!$C$2:$C$122))} -> -14885 | G43: =SUMIFS(D_DROT!$C$2:$C$122,D_DROT!$B$2:$B$122,"Wednesday") -> -67748.87 | H43: =COUNTIF(D_DROT!$B$2:$B$122,"Wednesday") -> 8
A44: Thursday | B44: =IFERROR(COUNTIFS(D_DROT!$B$2:$B$122,"Thursday",D_DROT!$C$2:$C$122,">0")/(COUNTIFS(D_DROT!$B$2:$B$122,"Thursday",D_DROT!$C$2:$C$122,">0")+COUNTIFS(D_DROT!$B$2:$B$122,"Thursday",D_DROT!$C$2:$C$122,"<0"))*100,0) -> 54.83871 | C44: =IFERROR(AVERAGEIFS(D_DROT!$C$2:$C$122,D_DROT!$B$2:$B$122,"Thursday",D_DROT!$C$2:$C$122,">0"),0) -> 19747.741 | D44: {=MAX(IF(D_DROT!$B$2:$B$122="Thursday",D_DROT!$C$2:$C$122))} -> 48217 | E44: =IFERROR(AVERAGEIFS(D_DROT!$C$2:$C$122,D_DROT!$B$2:$B$122,"Thursday",D_DROT!$C$2:$C$122,"<0"),0) -> -15285.847 | F44: {=MIN(IF(D_DROT!$B$2:$B$122="Thursday",D_DROT!$C$2:$C$122))} -> -41778.75 | G44: =SUMIFS(D_DROT!$C$2:$C$122,D_DROT!$B$2:$B$122,"Thursday") -> 121709.74 | H44: =COUNTIF(D_DROT!$B$2:$B$122,"Thursday") -> 31
A45: Friday | B45: =IFERROR(COUNTIFS(D_DROT!$B$2:$B$122,"Friday",D_DROT!$C$2:$C$122,">0")/(COUNTIFS(D_DROT!$B$2:$B$122,"Friday",D_DROT!$C$2:$C$122,">0")+COUNTIFS(D_DROT!$B$2:$B$122,"Friday",D_DROT!$C$2:$C$122,"<0"))*100,0) -> 46.153846 | C45: =IFERROR(AVERAGEIFS(D_DROT!$C$2:$C$122,D_DROT!$B$2:$B$122,"Friday",D_DROT!$C$2:$C$122,">0"),0) -> 18566.627 | D45: {=MAX(IF(D_DROT!$B$2:$B$122="Friday",D_DROT!$C$2:$C$122))} -> 38821.25 | E45: =IFERROR(AVERAGEIFS(D_DROT!$C$2:$C$122,D_DROT!$B$2:$B$122,"Friday",D_DROT!$C$2:$C$122,"<0"),0) -> -15386.95 | F45: {=MIN(IF(D_DROT!$B$2:$B$122="Friday",D_DROT!$C$2:$C$122))} -> -27987.87 | G45: =SUMIFS(D_DROT!$C$2:$C$122,D_DROT!$B$2:$B$122,"Friday") -> 7382.22 | H45: =COUNTIF(D_DROT!$B$2:$B$122,"Friday") -> 26
...

Sheet Combinations
A1: Combinations — Statistics A (basis Max Allocation)
A2: Including Wednesday
A3: Metric | B3: Combination 1 | C3: Combination 2 | D3: Combination 3
A4: Type | B4: Credit combo | C4: Credit combo | D4: Credit combo
A5: Allocation (Rs) | B5: =D_COMBO1!$T$1 -> 1600000 | C5: =D_COMBO2!$T$1 -> 1600000 | D5: =D_COMBO3!$T$1 -> 1700000
A6: Return 1M | B6: =SUMIFS(D_COMBO1!$C$2:$C$233,D_COMBO1!$A$2:$A$233,">="&D_COMBO1!$T$3)/D_COMBO1!$T$1*100 -> 12.066031 | C6: =SUMIFS(D_COMBO2!$C$2:$C$233,D_COMBO2!$A$2:$A$233,">="&D_COMBO2!$T$3)/D_COMBO2!$T$1*100 -> 12.066031 | D6: =SUMIFS(D_COMBO3!$C$2:$C$249,D_COMBO3!$A$2:$A$249,">="&D_COMBO3!$T$3)/D_COMBO3!$T$1*100 -> 13.197332
A7: Return 3M | B7: =SUMIFS(D_COMBO1!$C$2:$C$233,D_COMBO1!$A$2:$A$233,">="&D_COMBO1!$T$4)/D_COMBO1!$T$1*100 -> 52.923203 | C7: =SUMIFS(D_COMBO2!$C$2:$C$233,D_COMBO2!$A$2:$A$233,">="&D_COMBO2!$T$4)/D_COMBO2!$T$1*100 -> 52.923203 | D7: =SUMIFS(D_COMBO3!$C$2:$C$249,D_COMBO3!$A$2:$A$249,">="&D_COMBO3!$T$4)/D_COMBO3!$T$1*100 -> 53.056632
A8: Return 6M | B8: =SUMIFS(D_COMBO1!$C$2:$C$233,D_COMBO1!$A$2:$A$233,">="&D_COMBO1!$T$5)/D_COMBO1!$T$1*100 -> 91.216271 | C8: =SUMIFS(D_COMBO2!$C$2:$C$233,D_COMBO2!$A$2:$A$233,">="&D_COMBO2!$T$5)/D_COMBO2!$T$1*100 -> 91.216271 | D8: =SUMIFS(D_COMBO3!$C$2:$C$249,D_COMBO3!$A$2:$A$249,">="&D_COMBO3!$T$5)/D_COMBO3!$T$1*100 -> 92.27354
A9: Return 1Y | B9: =SUMIFS(D_COMBO1!$C$2:$C$233,D_COMBO1!$A$2:$A$233,">="&D_COMBO1!$T$6)/D_COMBO1!$T$1*100 -> 142.01055 | C9: =SUMIFS(D_COMBO2!$C$2:$C$233,D_COMBO2!$A$2:$A$233,">="&D_COMBO2!$T$6)/D_COMBO2!$T$1*100 -> 142.01055 | D9: =SUMIFS(D_COMBO3!$C$2:$C$249,D_COMBO3!$A$2:$A$249,">="&D_COMBO3!$T$6)/D_COMBO3!$T$1*100 -> 146.58573
A10: Return Max | B10: =SUM(D_COMBO1!$C$2:$C$233)/D_COMBO1!$T$1*100 -> 142.01055 | C10: =SUM(D_COMBO2!$C$2:$C$233)/D_COMBO2!$T$1*100 -> 142.01055 | D10: =SUM(D_COMBO3!$C$2:$C$249)/D_COMBO3!$T$1*100 -> 146.58573
A11: Gross Gain (Rs) | B11: =SUM(D_COMBO1!$C$2:$C$233) -> 2272168.8 | C11: =SUM(D_COMBO2!$C$2:$C$233) -> 2272168.8 | D11: =SUM(D_COMBO3!$C$2:$C$249) -> 2491957.4
A12: CAGR | B12: =((1+SUM(D_COMBO1!$C$2:$C$233)/D_COMBO1!$T$1)^(365/(D_COMBO1!$T$2-D_COMBO1!$T$9))-1)*100 -> 144.99958 | C12: =((1+SUM(D_COMBO2!$C$2:$C$233)/D_COMBO2!$T$1)^(365/(D_COMBO2!$T$2-D_COMBO2!$T$9))-1)*100 -> 144.99958 | D12: =((1+SUM(D_COMBO3!$C$2:$C$249)/D_COMBO3!$T$1)^(365/(D_COMBO3!$T$2-D_COMBO3!$T$9))-1)*100 -> 147.1979
A13: XIRR | B13: 252.3 | C13: 252.3 | D13: 256
A14: Avg Drawdown | B14: =AVERAGE(D_COMBO1!$G$2:$G$233) -> -1.2616036 | C14: =AVERAGE(D_COMBO2!$G$2:$G$233) -> -1.2616036 | D14: =AVERAGE(D_COMBO3!$G$2:$G$249) -> -1.2350085
A15: Max Drawdown | B15: =MIN(D_COMBO1!$G$2:$G$233) -> -8.3109575 | C15: =MIN(D_COMBO2!$G$2:$G$233) -> -8.3109575 | D15: =MIN(D_COMBO3!$G$2:$G$249) -> -9.3471688
A16: Success Ratio | B16: =COUNTIF(D_COMBO1!$C$2:$C$233,">0")/(COUNTIF(D_COMBO1!$C$2:$C$233,">0")+COUNTIF(D_COMBO1!$C$2:$C$233,"<0"))*100 -> 60.775862 | C16: =COUNTIF(D_COMBO2!$C$2:$C$233,">0")/(COUNTIF(D_COMBO2!$C$2:$C$233,">0")+COUNTIF(D_COMBO2!$C$2:$C$233,"<0"))*100 -> 60.775862 | D16: =COUNTIF(D_COMBO3!$C$2:$C$249,">0")/(COUNTIF(D_COMBO3!$C$2:$C$249,">0")+COUNTIF(D_COMBO3!$C$2:$C$249,"<0"))*100 -> 61.693548
A17: Risk : Reward | B17: =AVERAGEIF(D_COMBO1!$C$2:$C$233,">0")/-AVERAGEIF(D_COMBO1!$C$2:$C$233,"<0") -> 1.3459196 | C17: =AVERAGEIF(D_COMBO2!$C$2:$C$233,">0")/-AVERAGEIF(D_COMBO2!$C$2:$C$233,"<0") -> 1.3459196 | D17: =AVERAGEIF(D_COMBO3!$C$2:$C$249,">0")/-AVERAGEIF(D_COMBO3!$C$2:$C$249,"<0") -> 1.3220896
A18: Avg Profit /day (Rs) | B18: =AVERAGEIF(D_COMBO1!$C$2:$C$233,">0") -> 30960.942 | C18: =AVERAGEIF(D_COMBO2!$C$2:$C$233,">0") -> 30960.942 | D18: =AVERAGEIF(D_COMBO3!$C$2:$C$249,">0") -> 30710.291
A19: Avg Loss /day (Rs) | B19: =AVERAGEIF(D_COMBO1!$C$2:$C$233,"<0") -> -23003.56 | C19: =AVERAGEIF(D_COMBO2!$C$2:$C$233,"<0") -> -23003.56 | D19: =AVERAGEIF(D_COMBO3!$C$2:$C$249,"<0") -> -23228.6
A20: Avg Recovery (days) | B20: =AVERAGEIF(D_COMBO1!$J$2:$J$233,">0") -> 6.5217391 | C20: =AVERAGEIF(D_COMBO2!$J$2:$J$233,">0") -> 6.5217391 | D20: =AVERAGEIF(D_COMBO3!$J$2:$J$249,">0") -> 6.7906977
A21: Max Recovery (days) | B21: =MAX(MAX(D_COMBO1!$J$2:$J$233),D_COMBO1!$T$7) -> 25 | C21: =MAX(MAX(D_COMBO2!$J$2:$J$233),D_COMBO2!$T$7) -> 25 | D21: =MAX(MAX(D_COMBO3!$J$2:$J$249),D_COMBO3!$T$7) -> 23
A23: Excluding Wednesday (Wed P&L = 0)
A24: Metric | B24: Combination 1 | C24: Combination 2 | D24: Combination 3
A25: Type | B25: Credit combo | C25: Credit combo | D25: Credit combo
A26: Allocation (Rs) | B26: =D_COMBO1!$T$1 -> 1600000 | C26: =D_COMBO2!$T$1 -> 1600000 | D26: =D_COMBO3!$T$1 -> 1700000
A27: Return 1M | B27: =SUMIFS(D_COMBO1!$K$2:$K$233,D_COMBO1!$A$2:$A$233,">="&D_COMBO1!$T$3)/D_COMBO1!$T$1*100 -> 16.490094 | C27: =SUMIFS(D_COMBO2!$K$2:$K$233,D_COMBO2!$A$2:$A$233,">="&D_COMBO2!$T$3)/D_COMBO2!$T$1*100 -> 16.490094 | D27: =SUMIFS(D_COMBO3!$K$2:$K$249,D_COMBO3!$A$2:$A$249,">="&D_COMBO3!$T$3)/D_COMBO3!$T$1*100 -> 16.587312
A28: Return 3M | B28: =SUMIFS(D_COMBO1!$K$2:$K$233,D_COMBO1!$A$2:$A$233,">="&D_COMBO1!$T$4)/D_COMBO1!$T$1*100 -> 59.382375 | C28: =SUMIFS(D_COMBO2!$K$2:$K$233,D_COMBO2!$A$2:$A$233,">="&D_COMBO2!$T$4)/D_COMBO2!$T$1*100 -> 59.382375 | D28: =SUMIFS(D_COMBO3!$K$2:$K$249,D_COMBO3!$A$2:$A$249,">="&D_COMBO3!$T$4)/D_COMBO3!$T$1*100 -> 57.71155
A29: Return 6M | B29: =SUMIFS(D_COMBO1!$K$2:$K$233,D_COMBO1!$A$2:$A$233,">="&D_COMBO1!$T$5)/D_COMBO1!$T$1*100 -> 112.07624 | C29: =SUMIFS(D_COMBO2!$K$2:$K$233,D_COMBO2!$A$2:$A$233,">="&D_COMBO2!$T$5)/D_COMBO2!$T$1*100 -> 112.07624 | D29: =SUMIFS(D_COMBO3!$K$2:$K$249,D_COMBO3!$A$2:$A$249,">="&D_COMBO3!$T$5)/D_COMBO3!$T$1*100 -> 112.14122
A30: Return 1Y | B30: =SUMIFS(D_COMBO1!$K$2:$K$233,D_COMBO1!$A$2:$A$233,">="&D_COMBO1!$T$6)/D_COMBO1!$T$1*100 -> 164.38001 | C30: =SUMIFS(D_COMBO2!$K$2:$K$233,D_COMBO2!$A$2:$A$233,">="&D_COMBO2!$T$6)/D_COMBO2!$T$1*100 -> 164.38001 | D30: =SUMIFS(D_COMBO3!$K$2:$K$249,D_COMBO3!$A$2:$A$249,">="&D_COMBO3!$T$6)/D_COMBO3!$T$1*100 -> 168.67748
A31: Return Max | B31: =SUM(D_COMBO1!$K$2:$K$233)/D_COMBO1!$T$1*100 -> 164.38001 | C31: =SUM(D_COMBO2!$K$2:$K$233)/D_COMBO2!$T$1*100 -> 164.38001 | D31: =SUM(D_COMBO3!$K$2:$K$249)/D_COMBO3!$T$1*100 -> 168.67748
A32: Gross Gain (Rs) | B32: =SUM(D_COMBO1!$K$2:$K$233) -> 2630080.1 | C32: =SUM(D_COMBO2!$K$2:$K$233) -> 2630080.1 | D32: =SUM(D_COMBO3!$K$2:$K$249) -> 2867517.2
A33: CAGR | B33: =((1+SUM(D_COMBO1!$K$2:$K$233)/D_COMBO1!$T$1)^(365/(D_COMBO1!$T$2-D_COMBO1!$T$9))-1)*100 -> 167.97414 | C33: =((1+SUM(D_COMBO2!$K$2:$K$233)/D_COMBO2!$T$1)^(365/(D_COMBO2!$T$2-D_COMBO2!$T$9))-1)*100 -> 167.97414 | D33: =((1+SUM(D_COMBO3!$K$2:$K$249)/D_COMBO3!$T$1)^(365/(D_COMBO3!$T$2-D_COMBO3!$T$9))-1)*100 -> 169.40799
A34: XIRR | B34: 299.9 | C34: 299.9 | D34: 304.8
A35: Avg Drawdown | B35: =AVERAGE(D_COMBO1!$N$2:$N$233) -> -1.1155925 | C35: =AVERAGE(D_COMBO2!$N$2:$N$233) -> -1.1155925 | D35: =AVERAGE(D_COMBO3!$N$2:$N$249) -> -1.0322845
A36: Max Drawdown | B36: =MIN(D_COMBO1!$N$2:$N$233) -> -7.5326875 | C36: =MIN(D_COMBO2!$N$2:$N$233) -> -7.5326875 | D36: =MIN(D_COMBO3!$N$2:$N$249) -> -7.7891794
A37: Success Ratio | B37: =COUNTIF(D_COMBO1!$K$2:$K$233,">0")/(COUNTIF(D_COMBO1!$K$2:$K$233,">0")+COUNTIF(D_COMBO1!$K$2:$K$233,"<0"))*100 -> 64.705882 | C37: =COUNTIF(D_COMBO2!$K$2:$K$233,">0")/(COUNTIF(D_COMBO2!$K$2:$K$233,">0")+COUNTIF(D_COMBO2!$K$2:$K$233,"<0"))*100 -> 64.705882 | D37: =COUNTIF(D_COMBO3!$K$2:$K$249,">0")/(COUNTIF(D_COMBO3!$K$2:$K$249,">0")+COUNTIF(D_COMBO3!$K$2:$K$249,"<0"))*100 -> 65.656566
A38: Risk : Reward | B38: =AVERAGEIF(D_COMBO1!$K$2:$K$233,">0")/-AVERAGEIF(D_COMBO1!$K$2:$K$233,"<0") -> 1.4961844 | C38: =AVERAGEIF(D_COMBO2!$K$2:$K$233,">0")/-AVERAGEIF(D_COMBO2!$K$2:$K$233,"<0") -> 1.4961844 | D38: =AVERAGEIF(D_COMBO3!$K$2:$K$249,">0")/-AVERAGEIF(D_COMBO3!$K$2:$K$249,"<0") -> 1.4687252
A39: Avg Profit /day (Rs) | B39: =AVERAGEIF(D_COMBO1!$K$2:$K$233,">0") -> 34206.732 | C39: =AVERAGEIF(D_COMBO2!$K$2:$K$233,">0") -> 34206.732 | D39: =AVERAGEIF(D_COMBO3!$K$2:$K$249,">0") -> 34258.914
A40: Avg Loss /day (Rs) | B40: =AVERAGEIF(D_COMBO1!$K$2:$K$233,"<0") -> -22862.644 | C40: =AVERAGEIF(D_COMBO2!$K$2:$K$233,"<0") -> -22862.644 | D40: =AVERAGEIF(D_COMBO3!$K$2:$K$249,"<0") -> -23325.611
A41: Avg Recovery (days) | B41: =AVERAGEIF(D_COMBO1!$Q$2:$Q$233,">0") -> 6.6666667 | C41: =AVERAGEIF(D_COMBO2!$Q$2:$Q$233,">0") -> 6.6666667 | D41: =AVERAGEIF(D_COMBO3!$Q$2:$Q$249,">0") -> 7.2222222
...

Sheet Combinations - Day of Week
A1: Statistics B — Day-of-Week Performance (Combinations)
A3: Combination 1
A4: Weekday | B4: Success % | C4: Avg Profit (Rs) | D4: Max Profit (Rs) | E4: Avg Loss (Rs) | F4: Max Loss (Rs) | G4: Total P&L (Rs) | H4: # Days
A5: Monday | B5: =IFERROR(COUNTIFS(D_COMBO1!$B$2:$B$233,"Monday",D_COMBO1!$C$2:$C$233,">0")/(COUNTIFS(D_COMBO1!$B$2:$B$233,"Monday",D_COMBO1!$C$2:$C$233,">0")+COUNTIFS(D_COMBO1!$B$2:$B$233,"Monday",D_COMBO1!$C$2:$C$233,"<0"))*100,0) -> 54.901961 | C5: =IFERROR(AVERAGEIFS(D_COMBO1!$C$2:$C$233,D_COMBO1!$B$2:$B$233,"Monday",D_COMBO1!$C$2:$C$233,">0"),0) -> 34434.929 | D5: {=MAX(IF(D_COMBO1!$B$2:$B$233="Monday",D_COMBO1!$C$2:$C$233))} -> 80707.25 | E5: =IFERROR(AVERAGEIFS(D_COMBO1!$C$2:$C$233,D_COMBO1!$B$2:$B$233,"Monday",D_COMBO1!$C$2:$C$233,"<0"),0) -> -21439.28 | F5: {=MIN(IF(D_COMBO1!$B$2:$B$233="Monday",D_COMBO1!$C$2:$C$233))} -> -110740.5 | G5: =SUMIFS(D_COMBO1!$C$2:$C$233,D_COMBO1!$B$2:$B$233,"Monday") -> 471074.59 | H5: =COUNTIF(D_COMBO1!$B$2:$B$233,"Monday") -> 51
A6: Tuesday | B6: =IFERROR(COUNTIFS(D_COMBO1!$B$2:$B$233,"Tuesday",D_COMBO1!$C$2:$C$233,">0")/(COUNTIFS(D_COMBO1!$B$2:$B$233,"Tuesday",D_COMBO1!$C$2:$C$233,">0")+COUNTIFS(D_COMBO1!$B$2:$B$233,"Tuesday",D_COMBO1!$C$2:$C$233,"<0"))*100,0) -> 76.744186 | C6: =IFERROR(AVERAGEIFS(D_COMBO1!$C$2:$C$233,D_COMBO1!$B$2:$B$233,"Tuesday",D_COMBO1!$C$2:$C$233,">0"),0) -> 43400.587 | D6: {=MAX(IF(D_COMBO1!$B$2:$B$233="Tuesday",D_COMBO1!$C$2:$C$233))} -> 116109.5 | E6: =IFERROR(AVERAGEIFS(D_COMBO1!$C$2:$C$233,D_COMBO1!$B$2:$B$233,"Tuesday",D_COMBO1!$C$2:$C$233,"<0"),0) -> -16486.016 | F6: {=MIN(IF(D_COMBO1!$B$2:$B$233="Tuesday",D_COMBO1!$C$2:$C$233))} -> -26783.7 | G6: =SUMIFS(D_COMBO1!$C$2:$C$233,D_COMBO1!$B$2:$B$233,"Tuesday") -> 1267359.2 | H6: =COUNTIF(D_COMBO1!$B$2:$B$233,"Tuesday") -> 43
A7: Wednesday | B7: =IFERROR(COUNTIFS(D_COMBO1!$B$2:$B$233,"Wednesday",D_COMBO1!$C$2:$C$233,">0")/(COUNTIFS(D_COMBO1!$B$2:$B$233,"Wednesday",D_COMBO1!$C$2:$C$233,">0")+COUNTIFS(D_COMBO1!$B$2:$B$233,"Wednesday",D_COMBO1!$C$2:$C$233,"<0"))*100,0) -> 44.444444 | C7: =IFERROR(AVERAGEIFS(D_COMBO1!$C$2:$C$233,D_COMBO1!$B$2:$B$233,"Wednesday",D_COMBO1!$C$2:$C$233,">0"),0) -> 11323.913 | D7: {=MAX(IF(D_COMBO1!$B$2:$B$233="Wednesday",D_COMBO1!$C$2:$C$233))} -> 47388.37 | E7: =IFERROR(AVERAGEIFS(D_COMBO1!$C$2:$C$233,D_COMBO1!$B$2:$B$233,"Wednesday",D_COMBO1!$C$2:$C$233,"<0"),0) -> -23375.58 | F7: {=MIN(IF(D_COMBO1!$B$2:$B$233="Wednesday",D_COMBO1!$C$2:$C$233))} -> -104874.95 | G7: =SUMIFS(D_COMBO1!$C$2:$C$233,D_COMBO1!$B$2:$B$233,"Wednesday") -> -357911.24 | H7: =COUNTIF(D_COMBO1!$B$2:$B$233,"Wednesday") -> 45
A8: Thursday | B8: =IFERROR(COUNTIFS(D_COMBO1!$B$2:$B$233,"Thursday",D_COMBO1!$C$2:$C$233,">0")/(COUNTIFS(D_COMBO1!$B$2:$B$233,"Thursday",D_COMBO1!$C$2:$C$233,">0")+COUNTIFS(D_COMBO1!$B$2:$B$233,"Thursday",D_COMBO1!$C$2:$C$233,"<0"))*100,0) -> 73.913043 | C8: =IFERROR(AVERAGEIFS(D_COMBO1!$C$2:$C$233,D_COMBO1!$B$2:$B$233,"Thursday",D_COMBO1!$C$2:$C$233,">0"),0) -> 30598.183 | D8: {=MAX(IF(D_COMBO1!$B$2:$B$233="Thursday",D_COMBO1!$C$2:$C$233))} -> 80093 | E8: =IFERROR(AVERAGEIFS(D_COMBO1!$C$2:$C$233,D_COMBO1!$B$2:$B$233,"Thursday",D_COMBO1!$C$2:$C$233,"<0"),0) -> -27163.244 | F8: {=MIN(IF(D_COMBO1!$B$2:$B$233="Thursday",D_COMBO1!$C$2:$C$233))} -> -63389.12 | G8: =SUMIFS(D_COMBO1!$C$2:$C$233,D_COMBO1!$B$2:$B$233,"Thursday") -> 714379.3 | H8: =COUNTIF(D_COMBO1!$B$2:$B$233,"Thursday") -> 46
A9: Friday | B9: =IFERROR(COUNTIFS(D_COMBO1!$B$2:$B$233,"Friday",D_COMBO1!$C$2:$C$233,">0")/(COUNTIFS(D_COMBO1!$B$2:$B$233,"Friday",D_COMBO1!$C$2:$C$233,">0")+COUNTIFS(D_COMBO1!$B$2:$B$233,"Friday",D_COMBO1!$C$2:$C$233,"<0"))*100,0) -> 55.555556 | C9: =IFERROR(AVERAGEIFS(D_COMBO1!$C$2:$C$233,D_COMBO1!$B$2:$B$233,"Friday",D_COMBO1!$C$2:$C$233,">0"),0) -> 27256.37 | D9: {=MAX(IF(D_COMBO1!$B$2:$B$233="Friday",D_COMBO1!$C$2:$C$233))} -> 139664.37 | E9: =IFERROR(AVERAGEIFS(D_COMBO1!$C$2:$C$233,D_COMBO1!$B$2:$B$233,"Friday",D_COMBO1!$C$2:$C$233,"<0"),0) -> -23404.428 | F9: {=MIN(IF(D_COMBO1!$B$2:$B$233="Friday",D_COMBO1!$C$2:$C$233))} -> -96417.87 | G9: =SUMIFS(D_COMBO1!$C$2:$C$233,D_COMBO1!$B$2:$B$233,"Friday") -> 213320.68 | H9: =COUNTIF(D_COMBO1!$B$2:$B$233,"Friday") -> 45
A10: Best day (incl Wed) | B10: =INDEX($A$5:$A$9,MATCH(MAX($G$5:$G$9),$G$5:$G$9,0)) -> Tuesday | D10: Best day (excl Wed) | E10: =INDEX($A$5:$A$9,MATCH(MAX($G$5:$G$6,$G$8:$G$9),$G$5:$G$9,0)) -> Tuesday
A12: Combination 2
A13: Weekday | B13: Success % | C13: Avg Profit (Rs) | D13: Max Profit (Rs) | E13: Avg Loss (Rs) | F13: Max Loss (Rs) | G13: Total P&L (Rs) | H13: # Days
A14: Monday | B14: =IFERROR(COUNTIFS(D_COMBO2!$B$2:$B$233,"Monday",D_COMBO2!$C$2:$C$233,">0")/(COUNTIFS(D_COMBO2!$B$2:$B$233,"Monday",D_COMBO2!$C$2:$C$233,">0")+COUNTIFS(D_COMBO2!$B$2:$B$233,"Monday",D_COMBO2!$C$2:$C$233,"<0"))*100,0) -> 54.901961 | C14: =IFERROR(AVERAGEIFS(D_COMBO2!$C$2:$C$233,D_COMBO2!$B$2:$B$233,"Monday",D_COMBO2!$C$2:$C$233,">0"),0) -> 34434.929 | D14: {=MAX(IF(D_COMBO2!$B$2:$B$233="Monday",D_COMBO2!$C$2:$C$233))} -> 80707.25 | E14: =IFERROR(AVERAGEIFS(D_COMBO2!$C$2:$C$233,D_COMBO2!$B$2:$B$233,"Monday",D_COMBO2!$C$2:$C$233,"<0"),0) -> -21439.28 | F14: {=MIN(IF(D_COMBO2!$B$2:$B$233="Monday",D_COMBO2!$C$2:$C$233))} -> -110740.5 | G14: =SUMIFS(D_COMBO2!$C$2:$C$233,D_COMBO2!$B$2:$B$233,"Monday") -> 471074.59 | H14: =COUNTIF(D_COMBO2!$B$2:$B$233,"Monday") -> 51
A15: Tuesday | B15: =IFERROR(COUNTIFS(D_COMBO2!$B$2:$B$233,"Tuesday",D_COMBO2!$C$2:$C$233,">0")/(COUNTIFS(D_COMBO2!$B$2:$B$233,"Tuesday",D_COMBO2!$C$2:$C$233,">0")+COUNTIFS(D_COMBO2!$B$2:$B$233,"Tuesday",D_COMBO2!$C$2:$C$233,"<0"))*100,0) -> 76.744186 | C15: =IFERROR(AVERAGEIFS(D_COMBO2!$C$2:$C$233,D_COMBO2!$B$2:$B$233,"Tuesday",D_COMBO2!$C$2:$C$233,">0"),0) -> 43400.587 | D15: {=MAX(IF(D_COMBO2!$B$2:$B$233="Tuesday",D_COMBO2!$C$2:$C$233))} -> 116109.5 | E15: =IFERROR(AVERAGEIFS(D_COMBO2!$C$2:$C$233,D_COMBO2!$B$2:$B$233,"Tuesday",D_COMBO2!$C$2:$C$233,"<0"),0) -> -16486.016 | F15: {=MIN(IF(D_COMBO2!$B$2:$B$233="Tuesday",D_COMBO2!$C$2:$C$233))} -> -26783.7 | G15: =SUMIFS(D_COMBO2!$C$2:$C$233,D_COMBO2!$B$2:$B$233,"Tuesday") -> 1267359.2 | H15: =COUNTIF(D_COMBO2!$B$2:$B$233,"Tuesday") -> 43
A16: Wednesday | B16: =IFERROR(COUNTIFS(D_COMBO2!$B$2:$B$233,"Wednesday",D_COMBO2!$C$2:$C$233,">0")/(COUNTIFS(D_COMBO2!$B$2:$B$233,"Wednesday",D_COMBO2!$C$2:$C$233,">0")+COUNTIFS(D_COMBO2!$B$2:$B$233,"Wednesday",D_COMBO2!$C$2:$C$233,"<0"))*100,0) -> 44.444444 | C16: =IFERROR(AVERAGEIFS(D_COMBO2!$C$2:$C$233,D_COMBO2!$B$2:$B$233,"Wednesday",D_COMBO2!$C$2:$C$233,">0"),0) -> 11323.913 | D16: {=MAX(IF(D_COMBO2!$B$2:$B$233="Wednesday",D_COMBO2!$C$2:$C$233))} -> 47388.37 | E16: =IFERROR(AVERAGEIFS(D_COMBO2!$C$2:$C$233,D_COMBO2!$B$2:$B$233,"Wednesday",D_COMBO2!$C$2:$C$233,"<0"),0) -> -23375.58 | F16: {=MIN(IF(D_COMBO2!$B$2:$B$233="Wednesday",D_COMBO2!$C$2:$C$233))} -> -104874.95 | G16: =SUMIFS(D_COMBO2!$C$2:$C$233,D_COMBO2!$B$2:$B$233,"Wednesday") -> -357911.24 | H16: =COUNTIF(D_COMBO2!$B$2:$B$233,"Wednesday") -> 45
A17: Thursday | B17: =IFERROR(COUNTIFS(D_COMBO2!$B$2:$B$233,"Thursday",D_COMBO2!$C$2:$C$233,">0")/(COUNTIFS(D_COMBO2!$B$2:$B$233,"Thursday",D_COMBO2!$C$2:$C$233,">0")+COUNTIFS(D_COMBO2!$B$2:$B$233,"Thursday",D_COMBO2!$C$2:$C$233,"<0"))*100,0) -> 73.913043 | C17: =IFERROR(AVERAGEIFS(D_COMBO2!$C$2:$C$233,D_COMBO2!$B$2:$B$233,"Thursday",D_COMBO2!$C$2:$C$233,">0"),0) -> 30598.183 | D17: {=MAX(IF(D_COMBO2!$B$2:$B$233="Thursday",D_COMBO2!$C$2:$C$233))} -> 80093 | E17: =IFERROR(AVERAGEIFS(D_COMBO2!$C$2:$C$233,D_COMBO2!$B$2:$B$233,"Thursday",D_COMBO2!$C$2:$C$233,"<0"),0) -> -27163.244 | F17: {=MIN(IF(D_COMBO2!$B$2:$B$233="Thursday",D_COMBO2!$C$2:$C$233))} -> -63389.12 | G17: =SUMIFS(D_COMBO2!$C$2:$C$233,D_COMBO2!$B$2:$B$233,"Thursday") -> 714379.3 | H17: =COUNTIF(D_COMBO2!$B$2:$B$233,"Thursday") -> 46
A18: Friday | B18: =IFERROR(COUNTIFS(D_COMBO2!$B$2:$B$233,"Friday",D_COMBO2!$C$2:$C$233,">0")/(COUNTIFS(D_COMBO2!$B$2:$B$233,"Friday",D_COMBO2!$C$2:$C$233,">0")+COUNTIFS(D_COMBO2!$B$2:$B$233,"Friday",D_COMBO2!$C$2:$C$233,"<0"))*100,0) -> 55.555556 | C18: =IFERROR(AVERAGEIFS(D_COMBO2!$C$2:$C$233,D_COMBO2!$B$2:$B$233,"Friday",D_COMBO2!$C$2:$C$233,">0"),0) -> 27256.37 | D18: {=MAX(IF(D_COMBO2!$B$2:$B$233="Friday",D_COMBO2!$C$2:$C$233))} -> 139664.37 | E18: =IFERROR(AVERAGEIFS(D_COMBO2!$C$2:$C$233,D_COMBO2!$B$2:$B$233,"Friday",D_COMBO2!$C$2:$C$233,"<0"),0) -> -23404.428 | F18: {=MIN(IF(D_COMBO2!$B$2:$B$233="Friday",D_COMBO2!$C$2:$C$233))} -> -96417.87 | G18: =SUMIFS(D_COMBO2!$C$2:$C$233,D_COMBO2!$B$2:$B$233,"Friday") -> 213320.68 | H18: =COUNTIF(D_COMBO2!$B$2:$B$233,"Friday") -> 45
A19: Best day (incl Wed) | B19: =INDEX($A$14:$A$18,MATCH(MAX($G$14:$G$18),$G$14:$G$18,0)) -> Tuesday | D19: Best day (excl Wed) | E19: =INDEX($A$14:$A$18,MATCH(MAX($G$14:$G$15,$G$17:$G$18),$G$14:$G$18,0)) -> Tuesday
A21: Combination 3
A22: Weekday | B22: Success % | C22: Avg Profit (Rs) | D22: Max Profit (Rs) | E22: Avg Loss (Rs) | F22: Max Loss (Rs) | G22: Total P&L (Rs) | H22: # Days
A23: Monday | B23: =IFERROR(COUNTIFS(D_COMBO3!$B$2:$B$249,"Monday",D_COMBO3!$C$2:$C$249,">0")/(COUNTIFS(D_COMBO3!$B$2:$B$249,"Monday",D_COMBO3!$C$2:$C$249,">0")+COUNTIFS(D_COMBO3!$B$2:$B$249,"Monday",D_COMBO3!$C$2:$C$249,"<0"))*100,0) -> 65.384615 | C23: =IFERROR(AVERAGEIFS(D_COMBO3!$C$2:$C$249,D_COMBO3!$B$2:$B$249,"Monday",D_COMBO3!$C$2:$C$249,">0"),0) -> 32212.113 | D23: {=MAX(IF(D_COMBO3!$B$2:$B$249="Monday",D_COMBO3!$C$2:$C$249))} -> 90059.52 | E23: =IFERROR(AVERAGEIFS(D_COMBO3!$C$2:$C$249,D_COMBO3!$B$2:$B$249,"Monday",D_COMBO3!$C$2:$C$249,"<0"),0) -> -27502.744 | F23: {=MIN(IF(D_COMBO3!$B$2:$B$249="Monday",D_COMBO3!$C$2:$C$249))} -> -122707.65 | G23: =SUMIFS(D_COMBO3!$C$2:$C$249,D_COMBO3!$B$2:$B$249,"Monday") -> 600162.44 | H23: =COUNTIF(D_COMBO3!$B$2:$B$249,"Monday") -> 52
